sub-an041/sub-an041_ses-20140821_obj-17pzgym.nwb
Traceback (most recent call last):
  File "tools/populate_dandiset_asset_yamls.py", line 59, in main
    AssetMeta(**metadata)
  File "pydantic/main.py", line 362, in pydantic.main.BaseModel.__init__
pydantic.error_wrappers.ValidationError: 1 validation error for AssetMeta
identifier
  field required (type=value_error.missing)

sub-an041/sub-an041_ses-20140821_obj-jpt9d0.nwb
Traceback (most recent call last):
  File "tools/populate_dandiset_asset_yamls.py", line 59, in main
    AssetMeta(**metadata)
  File "pydantic/main.py", line 362, in pydantic.main.BaseModel.__init__
pydantic.error_wrappers.ValidationError: 1 validation error for AssetMeta
identifier
  field required (type=value_error.missing)

sub-an041/sub-an041_ses-20140823_obj-14abxhj.nwb
Traceback (most recent call last):
  File "tools/populate_dandiset_asset_yamls.py", line 59, in main
    AssetMeta(**metadata)
  File "pydantic/main.py", line 362, in pydantic.main.BaseModel.__init__
pydantic.error_wrappers.ValidationError: 1 validation error for AssetMeta
identifier
  field required (type=value_error.missing)

sub-an041/sub-an041_ses-20140823_obj-5qbi06.nwb
Traceback (most recent call last):
  File "tools/populate_dandiset_asset_yamls.py", line 59, in main
    AssetMeta(**metadata)
  File "pydantic/main.py", line 362, in pydantic.main.BaseModel.__init__
pydantic.error_wrappers.ValidationError: 1 validation error for AssetMeta
identifier
  field required (type=value_error.missing)

sub-an041/sub-an041_ses-20140823_obj-6xh5s8.nwb
Traceback (most recent call last):
  File "tools/populate_dandiset_asset_yamls.py", line 59, in main
    AssetMeta(**metadata)
  File "pydantic/main.py", line 362, in pydantic.main.BaseModel.__init__
pydantic.error_wrappers.ValidationError: 1 validation error for AssetMeta
identifier
  field required (type=value_error.missing)

sub-an041/sub-an041_ses-20140823_obj-9l0ag0.nwb
Traceback (most recent call last):
  File "tools/populate_dandiset_asset_yamls.py", line 59, in main
    AssetMeta(**metadata)
  File "pydantic/main.py", line 362, in pydantic.main.BaseModel.__init__
pydantic.error_wrappers.ValidationError: 1 validation error for AssetMeta
identifier
  field required (type=value_error.missing)

sub-an041/sub-an041_ses-20140823_obj-c486zn.nwb
Traceback (most recent call last):
  File "tools/populate_dandiset_asset_yamls.py", line 59, in main
    AssetMeta(**metadata)
  File "pydantic/main.py", line 362, in pydantic.main.BaseModel.__init__
pydantic.error_wrappers.ValidationError: 1 validation error for AssetMeta
identifier
  field required (type=value_error.missing)

sub-an041/sub-an041_ses-20140823_obj-m2u696.nwb
Traceback (most recent call last):
  File "tools/populate_dandiset_asset_yamls.py", line 59, in main
    AssetMeta(**metadata)
  File "pydantic/main.py", line 362, in pydantic.main.BaseModel.__init__
pydantic.error_wrappers.ValidationError: 1 validation error for AssetMeta
identifier
  field required (type=value_error.missing)

sub-an041/sub-an041_ses-20140825_obj-1k6balg.nwb
Traceback (most recent call last):
  File "tools/populate_dandiset_asset_yamls.py", line 59, in main
    AssetMeta(**metadata)
  File "pydantic/main.py", line 362, in pydantic.main.BaseModel.__init__
pydantic.error_wrappers.ValidationError: 1 validation error for AssetMeta
identifier
  field required (type=value_error.missing)

sub-an041/sub-an041_ses-20140825_obj-a0owv2.nwb
Traceback (most recent call last):
  File "tools/populate_dandiset_asset_yamls.py", line 59, in main
    AssetMeta(**metadata)
  File "pydantic/main.py", line 362, in pydantic.main.BaseModel.__init__
pydantic.error_wrappers.ValidationError: 1 validation error for AssetMeta
identifier
  field required (type=value_error.missing)

sub-an041/sub-an041_ses-20140825_obj-kghsci.nwb
Traceback (most recent call last):
  File "tools/populate_dandiset_asset_yamls.py", line 59, in main
    AssetMeta(**metadata)
  File "pydantic/main.py", line 362, in pydantic.main.BaseModel.__init__
pydantic.error_wrappers.ValidationError: 1 validation error for AssetMeta
identifier
  field required (type=value_error.missing)

sub-an041/sub-an041_ses-20140825_obj-mqj7rw.nwb
Traceback (most recent call last):
  File "tools/populate_dandiset_asset_yamls.py", line 59, in main
    AssetMeta(**metadata)
  File "pydantic/main.py", line 362, in pydantic.main.BaseModel.__init__
pydantic.error_wrappers.ValidationError: 1 validation error for AssetMeta
identifier
  field required (type=value_error.missing)

sub-an041/sub-an041_ses-20140825_obj-tu036r.nwb
Traceback (most recent call last):
  File "tools/populate_dandiset_asset_yamls.py", line 59, in main
    AssetMeta(**metadata)
  File "pydantic/main.py", line 362, in pydantic.main.BaseModel.__init__
pydantic.error_wrappers.ValidationError: 1 validation error for AssetMeta
identifier
  field required (type=value_error.missing)

sub-an041/sub-an041_ses-20140825_obj-w5c8hn.nwb
Traceback (most recent call last):
  File "tools/populate_dandiset_asset_yamls.py", line 59, in main
    AssetMeta(**metadata)
  File "pydantic/main.py", line 362, in pydantic.main.BaseModel.__init__
pydantic.error_wrappers.ValidationError: 1 validation error for AssetMeta
identifier
  field required (type=value_error.missing)

sub-an041/sub-an041_ses-20140826_obj-16dkvj5.nwb
Traceback (most recent call last):
  File "tools/populate_dandiset_asset_yamls.py", line 59, in main
    AssetMeta(**metadata)
  File "pydantic/main.py", line 362, in pydantic.main.BaseModel.__init__
pydantic.error_wrappers.ValidationError: 1 validation error for AssetMeta
identifier
  field required (type=value_error.missing)

sub-an041/sub-an041_ses-20140826_obj-1bb5khy.nwb
Traceback (most recent call last):
  File "tools/populate_dandiset_asset_yamls.py", line 59, in main
    AssetMeta(**metadata)
  File "pydantic/main.py", line 362, in pydantic.main.BaseModel.__init__
pydantic.error_wrappers.ValidationError: 1 validation error for AssetMeta
identifier
  field required (type=value_error.missing)

sub-an041/sub-an041_ses-20140826_obj-1hrk62p.nwb
Traceback (most recent call last):
  File "tools/populate_dandiset_asset_yamls.py", line 59, in main
    AssetMeta(**metadata)
  File "pydantic/main.py", line 362, in pydantic.main.BaseModel.__init__
pydantic.error_wrappers.ValidationError: 1 validation error for AssetMeta
identifier
  field required (type=value_error.missing)

sub-an041/sub-an041_ses-20140826_obj-1i6sh43.nwb
Traceback (most recent call last):
  File "tools/populate_dandiset_asset_yamls.py", line 59, in main
    AssetMeta(**metadata)
  File "pydantic/main.py", line 362, in pydantic.main.BaseModel.__init__
pydantic.error_wrappers.ValidationError: 1 validation error for AssetMeta
identifier
  field required (type=value_error.missing)

sub-an041/sub-an041_ses-20140826_obj-1jgvhk8.nwb
Traceback (most recent call last):
  File "tools/populate_dandiset_asset_yamls.py", line 59, in main
    AssetMeta(**metadata)
  File "pydantic/main.py", line 362, in pydantic.main.BaseModel.__init__
pydantic.error_wrappers.ValidationError: 1 validation error for AssetMeta
identifier
  field required (type=value_error.missing)

sub-an041/sub-an041_ses-20140826_obj-1k8h9e8.nwb
Traceback (most recent call last):
  File "tools/populate_dandiset_asset_yamls.py", line 59, in main
    AssetMeta(**metadata)
  File "pydantic/main.py", line 362, in pydantic.main.BaseModel.__init__
pydantic.error_wrappers.ValidationError: 1 validation error for AssetMeta
identifier
  field required (type=value_error.missing)

sub-an041/sub-an041_ses-20140826_obj-1mwtqg6.nwb
Traceback (most recent call last):
  File "tools/populate_dandiset_asset_yamls.py", line 59, in main
    AssetMeta(**metadata)
  File "pydantic/main.py", line 362, in pydantic.main.BaseModel.__init__
pydantic.error_wrappers.ValidationError: 1 validation error for AssetMeta
identifier
  field required (type=value_error.missing)

sub-an041/sub-an041_ses-20140826_obj-1q44jv8.nwb
Traceback (most recent call last):
  File "tools/populate_dandiset_asset_yamls.py", line 59, in main
    AssetMeta(**metadata)
  File "pydantic/main.py", line 362, in pydantic.main.BaseModel.__init__
pydantic.error_wrappers.ValidationError: 1 validation error for AssetMeta
identifier
  field required (type=value_error.missing)

sub-an041/sub-an041_ses-20140826_obj-4sg0j7.nwb
Traceback (most recent call last):
  File "tools/populate_dandiset_asset_yamls.py", line 59, in main
    AssetMeta(**metadata)
  File "pydantic/main.py", line 362, in pydantic.main.BaseModel.__init__
pydantic.error_wrappers.ValidationError: 1 validation error for AssetMeta
identifier
  field required (type=value_error.missing)

sub-an041/sub-an041_ses-20140826_obj-9afqt.nwb
Traceback (most recent call last):
  File "tools/populate_dandiset_asset_yamls.py", line 59, in main
    AssetMeta(**metadata)
  File "pydantic/main.py", line 362, in pydantic.main.BaseModel.__init__
pydantic.error_wrappers.ValidationError: 1 validation error for AssetMeta
identifier
  field required (type=value_error.missing)

sub-an041/sub-an041_ses-20140827_obj-134wql9.nwb
Traceback (most recent call last):
  File "tools/populate_dandiset_asset_yamls.py", line 59, in main
    AssetMeta(**metadata)
  File "pydantic/main.py", line 362, in pydantic.main.BaseModel.__init__
pydantic.error_wrappers.ValidationError: 1 validation error for AssetMeta
identifier
  field required (type=value_error.missing)

sub-an041/sub-an041_ses-20140827_obj-1gtn1pi.nwb
Traceback (most recent call last):
  File "tools/populate_dandiset_asset_yamls.py", line 59, in main
    AssetMeta(**metadata)
  File "pydantic/main.py", line 362, in pydantic.main.BaseModel.__init__
pydantic.error_wrappers.ValidationError: 1 validation error for AssetMeta
identifier
  field required (type=value_error.missing)

sub-an041/sub-an041_ses-20140827_obj-1jai2xh.nwb
Traceback (most recent call last):
  File "tools/populate_dandiset_asset_yamls.py", line 59, in main
    AssetMeta(**metadata)
  File "pydantic/main.py", line 362, in pydantic.main.BaseModel.__init__
pydantic.error_wrappers.ValidationError: 1 validation error for AssetMeta
identifier
  field required (type=value_error.missing)

sub-an041/sub-an041_ses-20140827_obj-1p56f6o.nwb
Traceback (most recent call last):
  File "tools/populate_dandiset_asset_yamls.py", line 59, in main
    AssetMeta(**metadata)
  File "pydantic/main.py", line 362, in pydantic.main.BaseModel.__init__
pydantic.error_wrappers.ValidationError: 1 validation error for AssetMeta
identifier
  field required (type=value_error.missing)

sub-an041/sub-an041_ses-20140827_obj-5qz3iv.nwb
Traceback (most recent call last):
  File "tools/populate_dandiset_asset_yamls.py", line 59, in main
    AssetMeta(**metadata)
  File "pydantic/main.py", line 362, in pydantic.main.BaseModel.__init__
pydantic.error_wrappers.ValidationError: 1 validation error for AssetMeta
identifier
  field required (type=value_error.missing)

sub-an041/sub-an041_ses-20140827_obj-dfhd5h.nwb
Traceback (most recent call last):
  File "tools/populate_dandiset_asset_yamls.py", line 59, in main
    AssetMeta(**metadata)
  File "pydantic/main.py", line 362, in pydantic.main.BaseModel.__init__
pydantic.error_wrappers.ValidationError: 1 validation error for AssetMeta
identifier
  field required (type=value_error.missing)

sub-an041/sub-an041_ses-20140827_obj-fcd5is.nwb
Traceback (most recent call last):
  File "tools/populate_dandiset_asset_yamls.py", line 59, in main
    AssetMeta(**metadata)
  File "pydantic/main.py", line 362, in pydantic.main.BaseModel.__init__
pydantic.error_wrappers.ValidationError: 1 validation error for AssetMeta
identifier
  field required (type=value_error.missing)

sub-an041/sub-an041_ses-20140827_obj-vooo3f.nwb
Traceback (most recent call last):
  File "tools/populate_dandiset_asset_yamls.py", line 59, in main
    AssetMeta(**metadata)
  File "pydantic/main.py", line 362, in pydantic.main.BaseModel.__init__
pydantic.error_wrappers.ValidationError: 1 validation error for AssetMeta
identifier
  field required (type=value_error.missing)

sub-an041/sub-an041_ses-20140903_obj-11gzsau.nwb
Traceback (most recent call last):
  File "tools/populate_dandiset_asset_yamls.py", line 59, in main
    AssetMeta(**metadata)
  File "pydantic/main.py", line 362, in pydantic.main.BaseModel.__init__
pydantic.error_wrappers.ValidationError: 1 validation error for AssetMeta
identifier
  field required (type=value_error.missing)

sub-an041/sub-an041_ses-20140903_obj-159kgs2.nwb
Traceback (most recent call last):
  File "tools/populate_dandiset_asset_yamls.py", line 59, in main
    AssetMeta(**metadata)
  File "pydantic/main.py", line 362, in pydantic.main.BaseModel.__init__
pydantic.error_wrappers.ValidationError: 1 validation error for AssetMeta
identifier
  field required (type=value_error.missing)

sub-an041/sub-an041_ses-20140903_obj-1lyfq5m.nwb
Traceback (most recent call last):
  File "tools/populate_dandiset_asset_yamls.py", line 59, in main
    AssetMeta(**metadata)
  File "pydantic/main.py", line 362, in pydantic.main.BaseModel.__init__
pydantic.error_wrappers.ValidationError: 1 validation error for AssetMeta
identifier
  field required (type=value_error.missing)

sub-an041/sub-an041_ses-20140903_obj-1ovbun9.nwb
Traceback (most recent call last):
  File "tools/populate_dandiset_asset_yamls.py", line 59, in main
    AssetMeta(**metadata)
  File "pydantic/main.py", line 362, in pydantic.main.BaseModel.__init__
pydantic.error_wrappers.ValidationError: 1 validation error for AssetMeta
identifier
  field required (type=value_error.missing)

sub-an041/sub-an041_ses-20140903_obj-1teaczs.nwb
Traceback (most recent call last):
  File "tools/populate_dandiset_asset_yamls.py", line 59, in main
    AssetMeta(**metadata)
  File "pydantic/main.py", line 362, in pydantic.main.BaseModel.__init__
pydantic.error_wrappers.ValidationError: 1 validation error for AssetMeta
identifier
  field required (type=value_error.missing)

sub-an041/sub-an041_ses-20140903_obj-1ufzyhq.nwb
Traceback (most recent call last):
  File "tools/populate_dandiset_asset_yamls.py", line 59, in main
    AssetMeta(**metadata)
  File "pydantic/main.py", line 362, in pydantic.main.BaseModel.__init__
pydantic.error_wrappers.ValidationError: 1 validation error for AssetMeta
identifier
  field required (type=value_error.missing)

sub-an041/sub-an041_ses-20140903_obj-6pdvnd.nwb
Traceback (most recent call last):
  File "tools/populate_dandiset_asset_yamls.py", line 59, in main
    AssetMeta(**metadata)
  File "pydantic/main.py", line 362, in pydantic.main.BaseModel.__init__
pydantic.error_wrappers.ValidationError: 1 validation error for AssetMeta
identifier
  field required (type=value_error.missing)

sub-an041/sub-an041_ses-20140903_obj-8nvb63.nwb
Traceback (most recent call last):
  File "tools/populate_dandiset_asset_yamls.py", line 59, in main
    AssetMeta(**metadata)
  File "pydantic/main.py", line 362, in pydantic.main.BaseModel.__init__
pydantic.error_wrappers.ValidationError: 1 validation error for AssetMeta
identifier
  field required (type=value_error.missing)

sub-an041/sub-an041_ses-20140903_obj-cpozn5.nwb
Traceback (most recent call last):
  File "tools/populate_dandiset_asset_yamls.py", line 59, in main
    AssetMeta(**metadata)
  File "pydantic/main.py", line 362, in pydantic.main.BaseModel.__init__
pydantic.error_wrappers.ValidationError: 1 validation error for AssetMeta
identifier
  field required (type=value_error.missing)

sub-an041/sub-an041_ses-20140903_obj-hif3fj.nwb
Traceback (most recent call last):
  File "tools/populate_dandiset_asset_yamls.py", line 59, in main
    AssetMeta(**metadata)
  File "pydantic/main.py", line 362, in pydantic.main.BaseModel.__init__
pydantic.error_wrappers.ValidationError: 1 validation error for AssetMeta
identifier
  field required (type=value_error.missing)

sub-an041/sub-an041_ses-20140903_obj-pfpcjq.nwb
Traceback (most recent call last):
  File "tools/populate_dandiset_asset_yamls.py", line 59, in main
    AssetMeta(**metadata)
  File "pydantic/main.py", line 362, in pydantic.main.BaseModel.__init__
pydantic.error_wrappers.ValidationError: 1 validation error for AssetMeta
identifier
  field required (type=value_error.missing)

sub-an041/sub-an041_ses-20140903_obj-pk9qdj.nwb
Traceback (most recent call last):
  File "tools/populate_dandiset_asset_yamls.py", line 59, in main
    AssetMeta(**metadata)
  File "pydantic/main.py", line 362, in pydantic.main.BaseModel.__init__
pydantic.error_wrappers.ValidationError: 1 validation error for AssetMeta
identifier
  field required (type=value_error.missing)

sub-an043/sub-an043_ses-20140904_obj-1d9fyha.nwb
Traceback (most recent call last):
  File "tools/populate_dandiset_asset_yamls.py", line 59, in main
    AssetMeta(**metadata)
  File "pydantic/main.py", line 362, in pydantic.main.BaseModel.__init__
pydantic.error_wrappers.ValidationError: 1 validation error for AssetMeta
identifier
  field required (type=value_error.missing)

sub-an043/sub-an043_ses-20140904_obj-1psv4mm.nwb
Traceback (most recent call last):
  File "tools/populate_dandiset_asset_yamls.py", line 59, in main
    AssetMeta(**metadata)
  File "pydantic/main.py", line 362, in pydantic.main.BaseModel.__init__
pydantic.error_wrappers.ValidationError: 1 validation error for AssetMeta
identifier
  field required (type=value_error.missing)

sub-an043/sub-an043_ses-20140904_obj-1uzd0hi.nwb
Traceback (most recent call last):
  File "tools/populate_dandiset_asset_yamls.py", line 59, in main
    AssetMeta(**metadata)
  File "pydantic/main.py", line 362, in pydantic.main.BaseModel.__init__
pydantic.error_wrappers.ValidationError: 1 validation error for AssetMeta
identifier
  field required (type=value_error.missing)

sub-an043/sub-an043_ses-20140904_obj-1vojhi0.nwb
Traceback (most recent call last):
  File "tools/populate_dandiset_asset_yamls.py", line 59, in main
    AssetMeta(**metadata)
  File "pydantic/main.py", line 362, in pydantic.main.BaseModel.__init__
pydantic.error_wrappers.ValidationError: 1 validation error for AssetMeta
identifier
  field required (type=value_error.missing)

sub-an043/sub-an043_ses-20140908_obj-17261dm.nwb
Traceback (most recent call last):
  File "tools/populate_dandiset_asset_yamls.py", line 59, in main
    AssetMeta(**metadata)
  File "pydantic/main.py", line 362, in pydantic.main.BaseModel.__init__
pydantic.error_wrappers.ValidationError: 1 validation error for AssetMeta
identifier
  field required (type=value_error.missing)

sub-an043/sub-an043_ses-20140908_obj-1btu7t9.nwb
Traceback (most recent call last):
  File "tools/populate_dandiset_asset_yamls.py", line 59, in main
    AssetMeta(**metadata)
  File "pydantic/main.py", line 362, in pydantic.main.BaseModel.__init__
pydantic.error_wrappers.ValidationError: 1 validation error for AssetMeta
identifier
  field required (type=value_error.missing)

sub-an043/sub-an043_ses-20140908_obj-1cpobhp.nwb
Traceback (most recent call last):
  File "tools/populate_dandiset_asset_yamls.py", line 59, in main
    AssetMeta(**metadata)
  File "pydantic/main.py", line 362, in pydantic.main.BaseModel.__init__
pydantic.error_wrappers.ValidationError: 1 validation error for AssetMeta
identifier
  field required (type=value_error.missing)

sub-an043/sub-an043_ses-20140908_obj-1fcrvgw.nwb
Traceback (most recent call last):
  File "tools/populate_dandiset_asset_yamls.py", line 59, in main
    AssetMeta(**metadata)
  File "pydantic/main.py", line 362, in pydantic.main.BaseModel.__init__
pydantic.error_wrappers.ValidationError: 1 validation error for AssetMeta
identifier
  field required (type=value_error.missing)

sub-an043/sub-an043_ses-20140908_obj-1zuk1g.nwb
Traceback (most recent call last):
  File "tools/populate_dandiset_asset_yamls.py", line 59, in main
    AssetMeta(**metadata)
  File "pydantic/main.py", line 362, in pydantic.main.BaseModel.__init__
pydantic.error_wrappers.ValidationError: 1 validation error for AssetMeta
identifier
  field required (type=value_error.missing)

sub-an043/sub-an043_ses-20140908_obj-8cuvgs.nwb
Traceback (most recent call last):
  File "tools/populate_dandiset_asset_yamls.py", line 59, in main
    AssetMeta(**metadata)
  File "pydantic/main.py", line 362, in pydantic.main.BaseModel.__init__
pydantic.error_wrappers.ValidationError: 1 validation error for AssetMeta
identifier
  field required (type=value_error.missing)

sub-an043/sub-an043_ses-20140909_obj-1fdkmhk.nwb
Traceback (most recent call last):
  File "tools/populate_dandiset_asset_yamls.py", line 59, in main
    AssetMeta(**metadata)
  File "pydantic/main.py", line 362, in pydantic.main.BaseModel.__init__
pydantic.error_wrappers.ValidationError: 1 validation error for AssetMeta
identifier
  field required (type=value_error.missing)

sub-an043/sub-an043_ses-20140909_obj-1k5ijvj.nwb
Traceback (most recent call last):
  File "tools/populate_dandiset_asset_yamls.py", line 59, in main
    AssetMeta(**metadata)
  File "pydantic/main.py", line 362, in pydantic.main.BaseModel.__init__
pydantic.error_wrappers.ValidationError: 1 validation error for AssetMeta
identifier
  field required (type=value_error.missing)

sub-an043/sub-an043_ses-20140909_obj-1pwrzqn.nwb
Traceback (most recent call last):
  File "tools/populate_dandiset_asset_yamls.py", line 59, in main
    AssetMeta(**metadata)
  File "pydantic/main.py", line 362, in pydantic.main.BaseModel.__init__
pydantic.error_wrappers.ValidationError: 1 validation error for AssetMeta
identifier
  field required (type=value_error.missing)

sub-an043/sub-an043_ses-20140909_obj-27temj.nwb
Traceback (most recent call last):
  File "tools/populate_dandiset_asset_yamls.py", line 59, in main
    AssetMeta(**metadata)
  File "pydantic/main.py", line 362, in pydantic.main.BaseModel.__init__
pydantic.error_wrappers.ValidationError: 1 validation error for AssetMeta
identifier
  field required (type=value_error.missing)

sub-an043/sub-an043_ses-20140909_obj-6vitlx.nwb
Traceback (most recent call last):
  File "tools/populate_dandiset_asset_yamls.py", line 59, in main
    AssetMeta(**metadata)
  File "pydantic/main.py", line 362, in pydantic.main.BaseModel.__init__
pydantic.error_wrappers.ValidationError: 1 validation error for AssetMeta
identifier
  field required (type=value_error.missing)

sub-an043/sub-an043_ses-20140909_obj-8wwv6n.nwb
Traceback (most recent call last):
  File "tools/populate_dandiset_asset_yamls.py", line 59, in main
    AssetMeta(**metadata)
  File "pydantic/main.py", line 362, in pydantic.main.BaseModel.__init__
pydantic.error_wrappers.ValidationError: 1 validation error for AssetMeta
identifier
  field required (type=value_error.missing)

sub-an043/sub-an043_ses-20140909_obj-ebvhu3.nwb
Traceback (most recent call last):
  File "tools/populate_dandiset_asset_yamls.py", line 59, in main
    AssetMeta(**metadata)
  File "pydantic/main.py", line 362, in pydantic.main.BaseModel.__init__
pydantic.error_wrappers.ValidationError: 1 validation error for AssetMeta
identifier
  field required (type=value_error.missing)

sub-an043/sub-an043_ses-20140909_obj-rgbsj.nwb
Traceback (most recent call last):
  File "tools/populate_dandiset_asset_yamls.py", line 59, in main
    AssetMeta(**metadata)
  File "pydantic/main.py", line 362, in pydantic.main.BaseModel.__init__
pydantic.error_wrappers.ValidationError: 1 validation error for AssetMeta
identifier
  field required (type=value_error.missing)

sub-an044/sub-an044_ses-20140915_obj-11nnwuf.nwb
Traceback (most recent call last):
  File "tools/populate_dandiset_asset_yamls.py", line 59, in main
    AssetMeta(**metadata)
  File "pydantic/main.py", line 362, in pydantic.main.BaseModel.__init__
pydantic.error_wrappers.ValidationError: 1 validation error for AssetMeta
identifier
  field required (type=value_error.missing)

sub-an044/sub-an044_ses-20140915_obj-1m3ozjr.nwb
Traceback (most recent call last):
  File "tools/populate_dandiset_asset_yamls.py", line 59, in main
    AssetMeta(**metadata)
  File "pydantic/main.py", line 362, in pydantic.main.BaseModel.__init__
pydantic.error_wrappers.ValidationError: 1 validation error for AssetMeta
identifier
  field required (type=value_error.missing)

sub-an044/sub-an044_ses-20140915_obj-leuiw7.nwb
Traceback (most recent call last):
  File "tools/populate_dandiset_asset_yamls.py", line 59, in main
    AssetMeta(**metadata)
  File "pydantic/main.py", line 362, in pydantic.main.BaseModel.__init__
pydantic.error_wrappers.ValidationError: 1 validation error for AssetMeta
identifier
  field required (type=value_error.missing)

sub-an044/sub-an044_ses-20140915_obj-q34v38.nwb
Traceback (most recent call last):
  File "tools/populate_dandiset_asset_yamls.py", line 59, in main
    AssetMeta(**metadata)
  File "pydantic/main.py", line 362, in pydantic.main.BaseModel.__init__
pydantic.error_wrappers.ValidationError: 1 validation error for AssetMeta
identifier
  field required (type=value_error.missing)

sub-an044/sub-an044_ses-20140921_obj-119qa5e.nwb
Traceback (most recent call last):
  File "tools/populate_dandiset_asset_yamls.py", line 59, in main
    AssetMeta(**metadata)
  File "pydantic/main.py", line 362, in pydantic.main.BaseModel.__init__
pydantic.error_wrappers.ValidationError: 1 validation error for AssetMeta
identifier
  field required (type=value_error.missing)

sub-an044/sub-an044_ses-20140921_obj-14vdgsa.nwb
Traceback (most recent call last):
  File "tools/populate_dandiset_asset_yamls.py", line 59, in main
    AssetMeta(**metadata)
  File "pydantic/main.py", line 362, in pydantic.main.BaseModel.__init__
pydantic.error_wrappers.ValidationError: 1 validation error for AssetMeta
identifier
  field required (type=value_error.missing)

sub-an044/sub-an044_ses-20140921_obj-1k0cq9z.nwb
Traceback (most recent call last):
  File "tools/populate_dandiset_asset_yamls.py", line 59, in main
    AssetMeta(**metadata)
  File "pydantic/main.py", line 362, in pydantic.main.BaseModel.__init__
pydantic.error_wrappers.ValidationError: 1 validation error for AssetMeta
identifier
  field required (type=value_error.missing)

sub-an044/sub-an044_ses-20140921_obj-izm82o.nwb
Traceback (most recent call last):
  File "tools/populate_dandiset_asset_yamls.py", line 59, in main
    AssetMeta(**metadata)
  File "pydantic/main.py", line 362, in pydantic.main.BaseModel.__init__
pydantic.error_wrappers.ValidationError: 1 validation error for AssetMeta
identifier
  field required (type=value_error.missing)

sub-an044/sub-an044_ses-20140922_obj-1d5hp9g.nwb
Traceback (most recent call last):
  File "tools/populate_dandiset_asset_yamls.py", line 59, in main
    AssetMeta(**metadata)
  File "pydantic/main.py", line 362, in pydantic.main.BaseModel.__init__
pydantic.error_wrappers.ValidationError: 1 validation error for AssetMeta
identifier
  field required (type=value_error.missing)

sub-an044/sub-an044_ses-20140922_obj-1ofupaz.nwb
Traceback (most recent call last):
  File "tools/populate_dandiset_asset_yamls.py", line 59, in main
    AssetMeta(**metadata)
  File "pydantic/main.py", line 362, in pydantic.main.BaseModel.__init__
pydantic.error_wrappers.ValidationError: 1 validation error for AssetMeta
identifier
  field required (type=value_error.missing)

sub-an044/sub-an044_ses-20140922_obj-1s9ir2j.nwb
Traceback (most recent call last):
  File "tools/populate_dandiset_asset_yamls.py", line 59, in main
    AssetMeta(**metadata)
  File "pydantic/main.py", line 362, in pydantic.main.BaseModel.__init__
pydantic.error_wrappers.ValidationError: 1 validation error for AssetMeta
identifier
  field required (type=value_error.missing)

sub-an044/sub-an044_ses-20140922_obj-1sihl7p.nwb
Traceback (most recent call last):
  File "tools/populate_dandiset_asset_yamls.py", line 59, in main
    AssetMeta(**metadata)
  File "pydantic/main.py", line 362, in pydantic.main.BaseModel.__init__
pydantic.error_wrappers.ValidationError: 1 validation error for AssetMeta
identifier
  field required (type=value_error.missing)

sub-an044/sub-an044_ses-20140922_obj-1w8xwi.nwb
Traceback (most recent call last):
  File "tools/populate_dandiset_asset_yamls.py", line 59, in main
    AssetMeta(**metadata)
  File "pydantic/main.py", line 362, in pydantic.main.BaseModel.__init__
pydantic.error_wrappers.ValidationError: 1 validation error for AssetMeta
identifier
  field required (type=value_error.missing)

sub-an044/sub-an044_ses-20140922_obj-3pn8ni.nwb
Traceback (most recent call last):
  File "tools/populate_dandiset_asset_yamls.py", line 59, in main
    AssetMeta(**metadata)
  File "pydantic/main.py", line 362, in pydantic.main.BaseModel.__init__
pydantic.error_wrappers.ValidationError: 1 validation error for AssetMeta
identifier
  field required (type=value_error.missing)

sub-an044/sub-an044_ses-20140923_obj-1dugu0v.nwb
Traceback (most recent call last):
  File "tools/populate_dandiset_asset_yamls.py", line 59, in main
    AssetMeta(**metadata)
  File "pydantic/main.py", line 362, in pydantic.main.BaseModel.__init__
pydantic.error_wrappers.ValidationError: 1 validation error for AssetMeta
identifier
  field required (type=value_error.missing)

sub-an044/sub-an044_ses-20140923_obj-1o335up.nwb
Traceback (most recent call last):
  File "tools/populate_dandiset_asset_yamls.py", line 59, in main
    AssetMeta(**metadata)
  File "pydantic/main.py", line 362, in pydantic.main.BaseModel.__init__
pydantic.error_wrappers.ValidationError: 1 validation error for AssetMeta
identifier
  field required (type=value_error.missing)

sub-an044/sub-an044_ses-20140923_obj-1sinakg.nwb
Traceback (most recent call last):
  File "tools/populate_dandiset_asset_yamls.py", line 59, in main
    AssetMeta(**metadata)
  File "pydantic/main.py", line 362, in pydantic.main.BaseModel.__init__
pydantic.error_wrappers.ValidationError: 1 validation error for AssetMeta
identifier
  field required (type=value_error.missing)

sub-an044/sub-an044_ses-20140923_obj-7yvntr.nwb
Traceback (most recent call last):
  File "tools/populate_dandiset_asset_yamls.py", line 59, in main
    AssetMeta(**metadata)
  File "pydantic/main.py", line 362, in pydantic.main.BaseModel.__init__
pydantic.error_wrappers.ValidationError: 1 validation error for AssetMeta
identifier
  field required (type=value_error.missing)

sub-an044/sub-an044_ses-20140923_obj-mcllak.nwb
Traceback (most recent call last):
  File "tools/populate_dandiset_asset_yamls.py", line 59, in main
    AssetMeta(**metadata)
  File "pydantic/main.py", line 362, in pydantic.main.BaseModel.__init__
pydantic.error_wrappers.ValidationError: 1 validation error for AssetMeta
identifier
  field required (type=value_error.missing)

sub-an044/sub-an044_ses-20140923_obj-wl7oh.nwb
Traceback (most recent call last):
  File "tools/populate_dandiset_asset_yamls.py", line 59, in main
    AssetMeta(**metadata)
  File "pydantic/main.py", line 362, in pydantic.main.BaseModel.__init__
pydantic.error_wrappers.ValidationError: 1 validation error for AssetMeta
identifier
  field required (type=value_error.missing)

sub-an044/sub-an044_ses-20140925_obj-1d3ze6d.nwb
Traceback (most recent call last):
  File "tools/populate_dandiset_asset_yamls.py", line 59, in main
    AssetMeta(**metadata)
  File "pydantic/main.py", line 362, in pydantic.main.BaseModel.__init__
pydantic.error_wrappers.ValidationError: 1 validation error for AssetMeta
identifier
  field required (type=value_error.missing)

sub-an044/sub-an044_ses-20140925_obj-1eikwlf.nwb
Traceback (most recent call last):
  File "tools/populate_dandiset_asset_yamls.py", line 59, in main
    AssetMeta(**metadata)
  File "pydantic/main.py", line 362, in pydantic.main.BaseModel.__init__
pydantic.error_wrappers.ValidationError: 1 validation error for AssetMeta
identifier
  field required (type=value_error.missing)

sub-an044/sub-an044_ses-20140925_obj-kt2npb.nwb
Traceback (most recent call last):
  File "tools/populate_dandiset_asset_yamls.py", line 59, in main
    AssetMeta(**metadata)
  File "pydantic/main.py", line 362, in pydantic.main.BaseModel.__init__
pydantic.error_wrappers.ValidationError: 1 validation error for AssetMeta
identifier
  field required (type=value_error.missing)

sub-an044/sub-an044_ses-20140925_obj-ymo12z.nwb
Traceback (most recent call last):
  File "tools/populate_dandiset_asset_yamls.py", line 59, in main
    AssetMeta(**metadata)
  File "pydantic/main.py", line 362, in pydantic.main.BaseModel.__init__
pydantic.error_wrappers.ValidationError: 1 validation error for AssetMeta
identifier
  field required (type=value_error.missing)

sub-an044/sub-an044_ses-20140929_obj-11h2y8j.nwb
Traceback (most recent call last):
  File "tools/populate_dandiset_asset_yamls.py", line 59, in main
    AssetMeta(**metadata)
  File "pydantic/main.py", line 362, in pydantic.main.BaseModel.__init__
pydantic.error_wrappers.ValidationError: 1 validation error for AssetMeta
identifier
  field required (type=value_error.missing)

sub-an044/sub-an044_ses-20140929_obj-1vm7imw.nwb
Traceback (most recent call last):
  File "tools/populate_dandiset_asset_yamls.py", line 59, in main
    AssetMeta(**metadata)
  File "pydantic/main.py", line 362, in pydantic.main.BaseModel.__init__
pydantic.error_wrappers.ValidationError: 1 validation error for AssetMeta
identifier
  field required (type=value_error.missing)

sub-an044/sub-an044_ses-20140929_obj-1ws5y5u.nwb
Traceback (most recent call last):
  File "tools/populate_dandiset_asset_yamls.py", line 59, in main
    AssetMeta(**metadata)
  File "pydantic/main.py", line 362, in pydantic.main.BaseModel.__init__
pydantic.error_wrappers.ValidationError: 1 validation error for AssetMeta
identifier
  field required (type=value_error.missing)

sub-an044/sub-an044_ses-20140929_obj-3fi722.nwb
Traceback (most recent call last):
  File "tools/populate_dandiset_asset_yamls.py", line 59, in main
    AssetMeta(**metadata)
  File "pydantic/main.py", line 362, in pydantic.main.BaseModel.__init__
pydantic.error_wrappers.ValidationError: 1 validation error for AssetMeta
identifier
  field required (type=value_error.missing)

sub-an044/sub-an044_ses-20140929_obj-fr88k9.nwb
Traceback (most recent call last):
  File "tools/populate_dandiset_asset_yamls.py", line 59, in main
    AssetMeta(**metadata)
  File "pydantic/main.py", line 362, in pydantic.main.BaseModel.__init__
pydantic.error_wrappers.ValidationError: 1 validation error for AssetMeta
identifier
  field required (type=value_error.missing)

sub-an044/sub-an044_ses-20140929_obj-s744ar.nwb
Traceback (most recent call last):
  File "tools/populate_dandiset_asset_yamls.py", line 59, in main
    AssetMeta(**metadata)
  File "pydantic/main.py", line 362, in pydantic.main.BaseModel.__init__
pydantic.error_wrappers.ValidationError: 1 validation error for AssetMeta
identifier
  field required (type=value_error.missing)

sub-an044/sub-an044_ses-20140930_obj-1ibzdpl.nwb
Traceback (most recent call last):
  File "tools/populate_dandiset_asset_yamls.py", line 59, in main
    AssetMeta(**metadata)
  File "pydantic/main.py", line 362, in pydantic.main.BaseModel.__init__
pydantic.error_wrappers.ValidationError: 1 validation error for AssetMeta
identifier
  field required (type=value_error.missing)

sub-an044/sub-an044_ses-20140930_obj-1vd1ono.nwb
Traceback (most recent call last):
  File "tools/populate_dandiset_asset_yamls.py", line 59, in main
    AssetMeta(**metadata)
  File "pydantic/main.py", line 362, in pydantic.main.BaseModel.__init__
pydantic.error_wrappers.ValidationError: 1 validation error for AssetMeta
identifier
  field required (type=value_error.missing)

sub-an044/sub-an044_ses-20140930_obj-5gl851.nwb
Traceback (most recent call last):
  File "tools/populate_dandiset_asset_yamls.py", line 59, in main
    AssetMeta(**metadata)
  File "pydantic/main.py", line 362, in pydantic.main.BaseModel.__init__
pydantic.error_wrappers.ValidationError: 1 validation error for AssetMeta
identifier
  field required (type=value_error.missing)

sub-an044/sub-an044_ses-20140930_obj-b4l53g.nwb
Traceback (most recent call last):
  File "tools/populate_dandiset_asset_yamls.py", line 59, in main
    AssetMeta(**metadata)
  File "pydantic/main.py", line 362, in pydantic.main.BaseModel.__init__
pydantic.error_wrappers.ValidationError: 1 validation error for AssetMeta
identifier
  field required (type=value_error.missing)

sub-an044/sub-an044_ses-20140930_obj-e1gnwj.nwb
Traceback (most recent call last):
  File "tools/populate_dandiset_asset_yamls.py", line 59, in main
    AssetMeta(**metadata)
  File "pydantic/main.py", line 362, in pydantic.main.BaseModel.__init__
pydantic.error_wrappers.ValidationError: 1 validation error for AssetMeta
identifier
  field required (type=value_error.missing)

sub-an044/sub-an044_ses-20140930_obj-ebi18k.nwb
Traceback (most recent call last):
  File "tools/populate_dandiset_asset_yamls.py", line 59, in main
    AssetMeta(**metadata)
  File "pydantic/main.py", line 362, in pydantic.main.BaseModel.__init__
pydantic.error_wrappers.ValidationError: 1 validation error for AssetMeta
identifier
  field required (type=value_error.missing)

sub-an044/sub-an044_ses-20140930_obj-o3x4z9.nwb
Traceback (most recent call last):
  File "tools/populate_dandiset_asset_yamls.py", line 59, in main
    AssetMeta(**metadata)
  File "pydantic/main.py", line 362, in pydantic.main.BaseModel.__init__
pydantic.error_wrappers.ValidationError: 1 validation error for AssetMeta
identifier
  field required (type=value_error.missing)

sub-an044/sub-an044_ses-20140930_obj-rauxs0.nwb
Traceback (most recent call last):
  File "tools/populate_dandiset_asset_yamls.py", line 59, in main
    AssetMeta(**metadata)
  File "pydantic/main.py", line 362, in pydantic.main.BaseModel.__init__
pydantic.error_wrappers.ValidationError: 1 validation error for AssetMeta
identifier
  field required (type=value_error.missing)

sub-an044/sub-an044_ses-20141006_obj-1c15qeb.nwb
Traceback (most recent call last):
  File "tools/populate_dandiset_asset_yamls.py", line 59, in main
    AssetMeta(**metadata)
  File "pydantic/main.py", line 362, in pydantic.main.BaseModel.__init__
pydantic.error_wrappers.ValidationError: 1 validation error for AssetMeta
identifier
  field required (type=value_error.missing)

sub-an044/sub-an044_ses-20141006_obj-3s9x4i.nwb
Traceback (most recent call last):
  File "tools/populate_dandiset_asset_yamls.py", line 59, in main
    AssetMeta(**metadata)
  File "pydantic/main.py", line 362, in pydantic.main.BaseModel.__init__
pydantic.error_wrappers.ValidationError: 1 validation error for AssetMeta
identifier
  field required (type=value_error.missing)

sub-an044/sub-an044_ses-20141006_obj-8y1chr.nwb
Traceback (most recent call last):
  File "tools/populate_dandiset_asset_yamls.py", line 59, in main
    AssetMeta(**metadata)
  File "pydantic/main.py", line 362, in pydantic.main.BaseModel.__init__
pydantic.error_wrappers.ValidationError: 1 validation error for AssetMeta
identifier
  field required (type=value_error.missing)

sub-an044/sub-an044_ses-20141006_obj-axqpak.nwb
Traceback (most recent call last):
  File "tools/populate_dandiset_asset_yamls.py", line 59, in main
    AssetMeta(**metadata)
  File "pydantic/main.py", line 362, in pydantic.main.BaseModel.__init__
pydantic.error_wrappers.ValidationError: 1 validation error for AssetMeta
identifier
  field required (type=value_error.missing)

sub-an044/sub-an044_ses-20141006_obj-n18815.nwb
Traceback (most recent call last):
  File "tools/populate_dandiset_asset_yamls.py", line 59, in main
    AssetMeta(**metadata)
  File "pydantic/main.py", line 362, in pydantic.main.BaseModel.__init__
pydantic.error_wrappers.ValidationError: 1 validation error for AssetMeta
identifier
  field required (type=value_error.missing)

sub-an044/sub-an044_ses-20141006_obj-o4unoi.nwb
Traceback (most recent call last):
  File "tools/populate_dandiset_asset_yamls.py", line 59, in main
    AssetMeta(**metadata)
  File "pydantic/main.py", line 362, in pydantic.main.BaseModel.__init__
pydantic.error_wrappers.ValidationError: 1 validation error for AssetMeta
identifier
  field required (type=value_error.missing)

sub-an044/sub-an044_ses-20141008_obj-1n07k9l.nwb
Traceback (most recent call last):
  File "tools/populate_dandiset_asset_yamls.py", line 59, in main
    AssetMeta(**metadata)
  File "pydantic/main.py", line 362, in pydantic.main.BaseModel.__init__
pydantic.error_wrappers.ValidationError: 1 validation error for AssetMeta
identifier
  field required (type=value_error.missing)

sub-an044/sub-an044_ses-20141008_obj-1opyyg3.nwb
Traceback (most recent call last):
  File "tools/populate_dandiset_asset_yamls.py", line 59, in main
    AssetMeta(**metadata)
  File "pydantic/main.py", line 362, in pydantic.main.BaseModel.__init__
pydantic.error_wrappers.ValidationError: 1 validation error for AssetMeta
identifier
  field required (type=value_error.missing)

sub-an044/sub-an044_ses-20141008_obj-2fqd7d.nwb
Traceback (most recent call last):
  File "tools/populate_dandiset_asset_yamls.py", line 59, in main
    AssetMeta(**metadata)
  File "pydantic/main.py", line 362, in pydantic.main.BaseModel.__init__
pydantic.error_wrappers.ValidationError: 1 validation error for AssetMeta
identifier
  field required (type=value_error.missing)

sub-an044/sub-an044_ses-20141008_obj-l21tog.nwb
Traceback (most recent call last):
  File "tools/populate_dandiset_asset_yamls.py", line 59, in main
    AssetMeta(**metadata)
  File "pydantic/main.py", line 362, in pydantic.main.BaseModel.__init__
pydantic.error_wrappers.ValidationError: 1 validation error for AssetMeta
identifier
  field required (type=value_error.missing)

sub-an044/sub-an044_ses-20141008_obj-pj86z6.nwb
Traceback (most recent call last):
  File "tools/populate_dandiset_asset_yamls.py", line 59, in main
    AssetMeta(**metadata)
  File "pydantic/main.py", line 362, in pydantic.main.BaseModel.__init__
pydantic.error_wrappers.ValidationError: 1 validation error for AssetMeta
identifier
  field required (type=value_error.missing)

sub-an044/sub-an044_ses-20141008_obj-v2ju38.nwb
Traceback (most recent call last):
  File "tools/populate_dandiset_asset_yamls.py", line 59, in main
    AssetMeta(**metadata)
  File "pydantic/main.py", line 362, in pydantic.main.BaseModel.__init__
pydantic.error_wrappers.ValidationError: 1 validation error for AssetMeta
identifier
  field required (type=value_error.missing)

sub-an044/sub-an044_ses-20141009_obj-1smq5mn.nwb
Traceback (most recent call last):
  File "tools/populate_dandiset_asset_yamls.py", line 59, in main
    AssetMeta(**metadata)
  File "pydantic/main.py", line 362, in pydantic.main.BaseModel.__init__
pydantic.error_wrappers.ValidationError: 1 validation error for AssetMeta
identifier
  field required (type=value_error.missing)

sub-an044/sub-an044_ses-20141009_obj-95ec2k.nwb
Traceback (most recent call last):
  File "tools/populate_dandiset_asset_yamls.py", line 59, in main
    AssetMeta(**metadata)
  File "pydantic/main.py", line 362, in pydantic.main.BaseModel.__init__
pydantic.error_wrappers.ValidationError: 1 validation error for AssetMeta
identifier
  field required (type=value_error.missing)

sub-an044/sub-an044_ses-20141009_obj-bihpoy.nwb
Traceback (most recent call last):
  File "tools/populate_dandiset_asset_yamls.py", line 59, in main
    AssetMeta(**metadata)
  File "pydantic/main.py", line 362, in pydantic.main.BaseModel.__init__
pydantic.error_wrappers.ValidationError: 1 validation error for AssetMeta
identifier
  field required (type=value_error.missing)

sub-an044/sub-an044_ses-20141009_obj-n039k0.nwb
Traceback (most recent call last):
  File "tools/populate_dandiset_asset_yamls.py", line 59, in main
    AssetMeta(**metadata)
  File "pydantic/main.py", line 362, in pydantic.main.BaseModel.__init__
pydantic.error_wrappers.ValidationError: 1 validation error for AssetMeta
identifier
  field required (type=value_error.missing)

sub-an063/sub-an063_ses-20150202_obj-1dka5up.nwb
Traceback (most recent call last):
  File "tools/populate_dandiset_asset_yamls.py", line 59, in main
    AssetMeta(**metadata)
  File "pydantic/main.py", line 362, in pydantic.main.BaseModel.__init__
pydantic.error_wrappers.ValidationError: 1 validation error for AssetMeta
identifier
  field required (type=value_error.missing)

sub-an063/sub-an063_ses-20150202_obj-1hqhbp5.nwb
Traceback (most recent call last):
  File "tools/populate_dandiset_asset_yamls.py", line 59, in main
    AssetMeta(**metadata)
  File "pydantic/main.py", line 362, in pydantic.main.BaseModel.__init__
pydantic.error_wrappers.ValidationError: 1 validation error for AssetMeta
identifier
  field required (type=value_error.missing)

sub-an063/sub-an063_ses-20150202_obj-1wsavki.nwb
Traceback (most recent call last):
  File "tools/populate_dandiset_asset_yamls.py", line 59, in main
    AssetMeta(**metadata)
  File "pydantic/main.py", line 362, in pydantic.main.BaseModel.__init__
pydantic.error_wrappers.ValidationError: 1 validation error for AssetMeta
identifier
  field required (type=value_error.missing)

sub-an063/sub-an063_ses-20150202_obj-5dkous.nwb
Traceback (most recent call last):
  File "tools/populate_dandiset_asset_yamls.py", line 59, in main
    AssetMeta(**metadata)
  File "pydantic/main.py", line 362, in pydantic.main.BaseModel.__init__
pydantic.error_wrappers.ValidationError: 1 validation error for AssetMeta
identifier
  field required (type=value_error.missing)

sub-an063/sub-an063_ses-20150202_obj-h8f1ho.nwb
Traceback (most recent call last):
  File "tools/populate_dandiset_asset_yamls.py", line 59, in main
    AssetMeta(**metadata)
  File "pydantic/main.py", line 362, in pydantic.main.BaseModel.__init__
pydantic.error_wrappers.ValidationError: 1 validation error for AssetMeta
identifier
  field required (type=value_error.missing)

sub-an063/sub-an063_ses-20150202_obj-suummr.nwb
Traceback (most recent call last):
  File "tools/populate_dandiset_asset_yamls.py", line 59, in main
    AssetMeta(**metadata)
  File "pydantic/main.py", line 362, in pydantic.main.BaseModel.__init__
pydantic.error_wrappers.ValidationError: 1 validation error for AssetMeta
identifier
  field required (type=value_error.missing)

sub-an063/sub-an063_ses-20150203_obj-14mczjs.nwb
Traceback (most recent call last):
  File "tools/populate_dandiset_asset_yamls.py", line 59, in main
    AssetMeta(**metadata)
  File "pydantic/main.py", line 362, in pydantic.main.BaseModel.__init__
pydantic.error_wrappers.ValidationError: 1 validation error for AssetMeta
identifier
  field required (type=value_error.missing)

sub-an063/sub-an063_ses-20150203_obj-14s3793.nwb
Traceback (most recent call last):
  File "tools/populate_dandiset_asset_yamls.py", line 59, in main
    AssetMeta(**metadata)
  File "pydantic/main.py", line 362, in pydantic.main.BaseModel.__init__
pydantic.error_wrappers.ValidationError: 1 validation error for AssetMeta
identifier
  field required (type=value_error.missing)

sub-an063/sub-an063_ses-20150203_obj-1i2x5ud.nwb
Traceback (most recent call last):
  File "tools/populate_dandiset_asset_yamls.py", line 59, in main
    AssetMeta(**metadata)
  File "pydantic/main.py", line 362, in pydantic.main.BaseModel.__init__
pydantic.error_wrappers.ValidationError: 1 validation error for AssetMeta
identifier
  field required (type=value_error.missing)

sub-an063/sub-an063_ses-20150203_obj-2xsvq9.nwb
Traceback (most recent call last):
  File "tools/populate_dandiset_asset_yamls.py", line 59, in main
    AssetMeta(**metadata)
  File "pydantic/main.py", line 362, in pydantic.main.BaseModel.__init__
pydantic.error_wrappers.ValidationError: 1 validation error for AssetMeta
identifier
  field required (type=value_error.missing)

sub-an063/sub-an063_ses-20150203_obj-nooo5m.nwb
Traceback (most recent call last):
  File "tools/populate_dandiset_asset_yamls.py", line 59, in main
    AssetMeta(**metadata)
  File "pydantic/main.py", line 362, in pydantic.main.BaseModel.__init__
pydantic.error_wrappers.ValidationError: 1 validation error for AssetMeta
identifier
  field required (type=value_error.missing)

sub-an063/sub-an063_ses-20150203_obj-o3a2bp.nwb
Traceback (most recent call last):
  File "tools/populate_dandiset_asset_yamls.py", line 59, in main
    AssetMeta(**metadata)
  File "pydantic/main.py", line 362, in pydantic.main.BaseModel.__init__
pydantic.error_wrappers.ValidationError: 1 validation error for AssetMeta
identifier
  field required (type=value_error.missing)

sub-an063/sub-an063_ses-20150204_obj-1383d52.nwb
Traceback (most recent call last):
  File "tools/populate_dandiset_asset_yamls.py", line 59, in main
    AssetMeta(**metadata)
  File "pydantic/main.py", line 362, in pydantic.main.BaseModel.__init__
pydantic.error_wrappers.ValidationError: 1 validation error for AssetMeta
identifier
  field required (type=value_error.missing)

sub-an063/sub-an063_ses-20150204_obj-1fndaqz.nwb
Traceback (most recent call last):
  File "tools/populate_dandiset_asset_yamls.py", line 59, in main
    AssetMeta(**metadata)
  File "pydantic/main.py", line 362, in pydantic.main.BaseModel.__init__
pydantic.error_wrappers.ValidationError: 1 validation error for AssetMeta
identifier
  field required (type=value_error.missing)

sub-an063/sub-an063_ses-20150204_obj-vr71qv.nwb
Traceback (most recent call last):
  File "tools/populate_dandiset_asset_yamls.py", line 59, in main
    AssetMeta(**metadata)
  File "pydantic/main.py", line 362, in pydantic.main.BaseModel.__init__
pydantic.error_wrappers.ValidationError: 1 validation error for AssetMeta
identifier
  field required (type=value_error.missing)

sub-an063/sub-an063_ses-20150204_obj-xxcliq.nwb
Traceback (most recent call last):
  File "tools/populate_dandiset_asset_yamls.py", line 59, in main
    AssetMeta(**metadata)
  File "pydantic/main.py", line 362, in pydantic.main.BaseModel.__init__
pydantic.error_wrappers.ValidationError: 1 validation error for AssetMeta
identifier
  field required (type=value_error.missing)

sub-an063/sub-an063_ses-20150206_obj-18cr6bf.nwb
Traceback (most recent call last):
  File "tools/populate_dandiset_asset_yamls.py", line 59, in main
    AssetMeta(**metadata)
  File "pydantic/main.py", line 362, in pydantic.main.BaseModel.__init__
pydantic.error_wrappers.ValidationError: 1 validation error for AssetMeta
identifier
  field required (type=value_error.missing)

sub-an063/sub-an063_ses-20150206_obj-1a5kxg1.nwb
Traceback (most recent call last):
  File "tools/populate_dandiset_asset_yamls.py", line 59, in main
    AssetMeta(**metadata)
  File "pydantic/main.py", line 362, in pydantic.main.BaseModel.__init__
pydantic.error_wrappers.ValidationError: 1 validation error for AssetMeta
identifier
  field required (type=value_error.missing)

sub-an063/sub-an063_ses-20150206_obj-1bn4h5y.nwb
Traceback (most recent call last):
  File "tools/populate_dandiset_asset_yamls.py", line 59, in main
    AssetMeta(**metadata)
  File "pydantic/main.py", line 362, in pydantic.main.BaseModel.__init__
pydantic.error_wrappers.ValidationError: 1 validation error for AssetMeta
identifier
  field required (type=value_error.missing)

sub-an063/sub-an063_ses-20150206_obj-1vblayf.nwb
Traceback (most recent call last):
  File "tools/populate_dandiset_asset_yamls.py", line 59, in main
    AssetMeta(**metadata)
  File "pydantic/main.py", line 362, in pydantic.main.BaseModel.__init__
pydantic.error_wrappers.ValidationError: 1 validation error for AssetMeta
identifier
  field required (type=value_error.missing)

sub-an063/sub-an063_ses-20150206_obj-8tb17u.nwb
Traceback (most recent call last):
  File "tools/populate_dandiset_asset_yamls.py", line 59, in main
    AssetMeta(**metadata)
  File "pydantic/main.py", line 362, in pydantic.main.BaseModel.__init__
pydantic.error_wrappers.ValidationError: 1 validation error for AssetMeta
identifier
  field required (type=value_error.missing)

sub-an063/sub-an063_ses-20150206_obj-p1fs4e.nwb
Traceback (most recent call last):
  File "tools/populate_dandiset_asset_yamls.py", line 59, in main
    AssetMeta(**metadata)
  File "pydantic/main.py", line 362, in pydantic.main.BaseModel.__init__
pydantic.error_wrappers.ValidationError: 1 validation error for AssetMeta
identifier
  field required (type=value_error.missing)

sub-an063/sub-an063_ses-20150206_obj-ugeg07.nwb
Traceback (most recent call last):
  File "tools/populate_dandiset_asset_yamls.py", line 59, in main
    AssetMeta(**metadata)
  File "pydantic/main.py", line 362, in pydantic.main.BaseModel.__init__
pydantic.error_wrappers.ValidationError: 1 validation error for AssetMeta
identifier
  field required (type=value_error.missing)

sub-an063/sub-an063_ses-20150206_obj-zzwpbf.nwb
Traceback (most recent call last):
  File "tools/populate_dandiset_asset_yamls.py", line 59, in main
    AssetMeta(**metadata)
  File "pydantic/main.py", line 362, in pydantic.main.BaseModel.__init__
pydantic.error_wrappers.ValidationError: 1 validation error for AssetMeta
identifier
  field required (type=value_error.missing)

sub-an063/sub-an063_ses-20150209_obj-11bsnmh.nwb
Traceback (most recent call last):
  File "tools/populate_dandiset_asset_yamls.py", line 59, in main
    AssetMeta(**metadata)
  File "pydantic/main.py", line 362, in pydantic.main.BaseModel.__init__
pydantic.error_wrappers.ValidationError: 1 validation error for AssetMeta
identifier
  field required (type=value_error.missing)

sub-an063/sub-an063_ses-20150209_obj-1aj2i7o.nwb
Traceback (most recent call last):
  File "tools/populate_dandiset_asset_yamls.py", line 59, in main
    AssetMeta(**metadata)
  File "pydantic/main.py", line 362, in pydantic.main.BaseModel.__init__
pydantic.error_wrappers.ValidationError: 1 validation error for AssetMeta
identifier
  field required (type=value_error.missing)

sub-an063/sub-an063_ses-20150209_obj-1gjcsui.nwb
Traceback (most recent call last):
  File "tools/populate_dandiset_asset_yamls.py", line 59, in main
    AssetMeta(**metadata)
  File "pydantic/main.py", line 362, in pydantic.main.BaseModel.__init__
pydantic.error_wrappers.ValidationError: 1 validation error for AssetMeta
identifier
  field required (type=value_error.missing)

sub-an063/sub-an063_ses-20150209_obj-1grkv6m.nwb
Traceback (most recent call last):
  File "tools/populate_dandiset_asset_yamls.py", line 59, in main
    AssetMeta(**metadata)
  File "pydantic/main.py", line 362, in pydantic.main.BaseModel.__init__
pydantic.error_wrappers.ValidationError: 1 validation error for AssetMeta
identifier
  field required (type=value_error.missing)

sub-an063/sub-an063_ses-20150209_obj-1tsiylt.nwb
Traceback (most recent call last):
  File "tools/populate_dandiset_asset_yamls.py", line 59, in main
    AssetMeta(**metadata)
  File "pydantic/main.py", line 362, in pydantic.main.BaseModel.__init__
pydantic.error_wrappers.ValidationError: 1 validation error for AssetMeta
identifier
  field required (type=value_error.missing)

sub-an063/sub-an063_ses-20150209_obj-1tztuv4.nwb
Traceback (most recent call last):
  File "tools/populate_dandiset_asset_yamls.py", line 59, in main
    AssetMeta(**metadata)
  File "pydantic/main.py", line 362, in pydantic.main.BaseModel.__init__
pydantic.error_wrappers.ValidationError: 1 validation error for AssetMeta
identifier
  field required (type=value_error.missing)

sub-an063/sub-an063_ses-20150209_obj-2zeyhf.nwb
Traceback (most recent call last):
  File "tools/populate_dandiset_asset_yamls.py", line 59, in main
    AssetMeta(**metadata)
  File "pydantic/main.py", line 362, in pydantic.main.BaseModel.__init__
pydantic.error_wrappers.ValidationError: 1 validation error for AssetMeta
identifier
  field required (type=value_error.missing)

sub-an063/sub-an063_ses-20150209_obj-kmhsto.nwb
Traceback (most recent call last):
  File "tools/populate_dandiset_asset_yamls.py", line 59, in main
    AssetMeta(**metadata)
  File "pydantic/main.py", line 362, in pydantic.main.BaseModel.__init__
pydantic.error_wrappers.ValidationError: 1 validation error for AssetMeta
identifier
  field required (type=value_error.missing)

sub-an063/sub-an063_ses-20150212_obj-175nvqu.nwb
Traceback (most recent call last):
  File "tools/populate_dandiset_asset_yamls.py", line 59, in main
    AssetMeta(**metadata)
  File "pydantic/main.py", line 362, in pydantic.main.BaseModel.__init__
pydantic.error_wrappers.ValidationError: 1 validation error for AssetMeta
identifier
  field required (type=value_error.missing)

sub-an063/sub-an063_ses-20150212_obj-1m4d9zo.nwb
Traceback (most recent call last):
  File "tools/populate_dandiset_asset_yamls.py", line 59, in main
    AssetMeta(**metadata)
  File "pydantic/main.py", line 362, in pydantic.main.BaseModel.__init__
pydantic.error_wrappers.ValidationError: 1 validation error for AssetMeta
identifier
  field required (type=value_error.missing)

sub-an063/sub-an063_ses-20150212_obj-1o5futo.nwb
Traceback (most recent call last):
  File "tools/populate_dandiset_asset_yamls.py", line 59, in main
    AssetMeta(**metadata)
  File "pydantic/main.py", line 362, in pydantic.main.BaseModel.__init__
pydantic.error_wrappers.ValidationError: 1 validation error for AssetMeta
identifier
  field required (type=value_error.missing)

sub-an063/sub-an063_ses-20150212_obj-1oev14d.nwb
Traceback (most recent call last):
  File "tools/populate_dandiset_asset_yamls.py", line 59, in main
    AssetMeta(**metadata)
  File "pydantic/main.py", line 362, in pydantic.main.BaseModel.__init__
pydantic.error_wrappers.ValidationError: 1 validation error for AssetMeta
identifier
  field required (type=value_error.missing)

sub-an063/sub-an063_ses-20150212_obj-20zoqo.nwb
Traceback (most recent call last):
  File "tools/populate_dandiset_asset_yamls.py", line 59, in main
    AssetMeta(**metadata)
  File "pydantic/main.py", line 362, in pydantic.main.BaseModel.__init__
pydantic.error_wrappers.ValidationError: 1 validation error for AssetMeta
identifier
  field required (type=value_error.missing)

sub-an063/sub-an063_ses-20150212_obj-6qmdsc.nwb
Traceback (most recent call last):
  File "tools/populate_dandiset_asset_yamls.py", line 59, in main
    AssetMeta(**metadata)
  File "pydantic/main.py", line 362, in pydantic.main.BaseModel.__init__
pydantic.error_wrappers.ValidationError: 1 validation error for AssetMeta
identifier
  field required (type=value_error.missing)

sub-an063/sub-an063_ses-20150212_obj-ras7d.nwb
Traceback (most recent call last):
  File "tools/populate_dandiset_asset_yamls.py", line 59, in main
    AssetMeta(**metadata)
  File "pydantic/main.py", line 362, in pydantic.main.BaseModel.__init__
pydantic.error_wrappers.ValidationError: 1 validation error for AssetMeta
identifier
  field required (type=value_error.missing)

sub-an063/sub-an063_ses-20150212_obj-skiwgj.nwb
Traceback (most recent call last):
  File "tools/populate_dandiset_asset_yamls.py", line 59, in main
    AssetMeta(**metadata)
  File "pydantic/main.py", line 362, in pydantic.main.BaseModel.__init__
pydantic.error_wrappers.ValidationError: 1 validation error for AssetMeta
identifier
  field required (type=value_error.missing)

sub-an064/sub-an064_ses-20150210_obj-kschv7.nwb
Traceback (most recent call last):
  File "tools/populate_dandiset_asset_yamls.py", line 59, in main
    AssetMeta(**metadata)
  File "pydantic/main.py", line 362, in pydantic.main.BaseModel.__init__
pydantic.error_wrappers.ValidationError: 1 validation error for AssetMeta
identifier
  field required (type=value_error.missing)

sub-an064/sub-an064_ses-20150210_obj-n49zw2.nwb
Traceback (most recent call last):
  File "tools/populate_dandiset_asset_yamls.py", line 59, in main
    AssetMeta(**metadata)
  File "pydantic/main.py", line 362, in pydantic.main.BaseModel.__init__
pydantic.error_wrappers.ValidationError: 1 validation error for AssetMeta
identifier
  field required (type=value_error.missing)

sub-an064/sub-an064_ses-20150210_obj-pg3siu.nwb
Traceback (most recent call last):
  File "tools/populate_dandiset_asset_yamls.py", line 59, in main
    AssetMeta(**metadata)
  File "pydantic/main.py", line 362, in pydantic.main.BaseModel.__init__
pydantic.error_wrappers.ValidationError: 1 validation error for AssetMeta
identifier
  field required (type=value_error.missing)

sub-an064/sub-an064_ses-20150210_obj-rkekbv.nwb
Traceback (most recent call last):
  File "tools/populate_dandiset_asset_yamls.py", line 59, in main
    AssetMeta(**metadata)
  File "pydantic/main.py", line 362, in pydantic.main.BaseModel.__init__
pydantic.error_wrappers.ValidationError: 1 validation error for AssetMeta
identifier
  field required (type=value_error.missing)

sub-an064/sub-an064_ses-20150211_obj-128cdly.nwb
Traceback (most recent call last):
  File "tools/populate_dandiset_asset_yamls.py", line 59, in main
    AssetMeta(**metadata)
  File "pydantic/main.py", line 362, in pydantic.main.BaseModel.__init__
pydantic.error_wrappers.ValidationError: 1 validation error for AssetMeta
identifier
  field required (type=value_error.missing)

sub-an064/sub-an064_ses-20150211_obj-13oug0a.nwb
Traceback (most recent call last):
  File "tools/populate_dandiset_asset_yamls.py", line 59, in main
    AssetMeta(**metadata)
  File "pydantic/main.py", line 362, in pydantic.main.BaseModel.__init__
pydantic.error_wrappers.ValidationError: 1 validation error for AssetMeta
identifier
  field required (type=value_error.missing)

sub-an064/sub-an064_ses-20150211_obj-18i0d18.nwb
Traceback (most recent call last):
  File "tools/populate_dandiset_asset_yamls.py", line 59, in main
    AssetMeta(**metadata)
  File "pydantic/main.py", line 362, in pydantic.main.BaseModel.__init__
pydantic.error_wrappers.ValidationError: 1 validation error for AssetMeta
identifier
  field required (type=value_error.missing)

sub-an064/sub-an064_ses-20150211_obj-1kfygix.nwb
Traceback (most recent call last):
  File "tools/populate_dandiset_asset_yamls.py", line 59, in main
    AssetMeta(**metadata)
  File "pydantic/main.py", line 362, in pydantic.main.BaseModel.__init__
pydantic.error_wrappers.ValidationError: 1 validation error for AssetMeta
identifier
  field required (type=value_error.missing)

sub-an064/sub-an064_ses-20150211_obj-b3siem.nwb
Traceback (most recent call last):
  File "tools/populate_dandiset_asset_yamls.py", line 59, in main
    AssetMeta(**metadata)
  File "pydantic/main.py", line 362, in pydantic.main.BaseModel.__init__
pydantic.error_wrappers.ValidationError: 1 validation error for AssetMeta
identifier
  field required (type=value_error.missing)

sub-an064/sub-an064_ses-20150211_obj-e6wfj1.nwb
Traceback (most recent call last):
  File "tools/populate_dandiset_asset_yamls.py", line 59, in main
    AssetMeta(**metadata)
  File "pydantic/main.py", line 362, in pydantic.main.BaseModel.__init__
pydantic.error_wrappers.ValidationError: 1 validation error for AssetMeta
identifier
  field required (type=value_error.missing)

sub-an064/sub-an064_ses-20150214_obj-13brclo.nwb
Traceback (most recent call last):
  File "tools/populate_dandiset_asset_yamls.py", line 59, in main
    AssetMeta(**metadata)
  File "pydantic/main.py", line 362, in pydantic.main.BaseModel.__init__
pydantic.error_wrappers.ValidationError: 1 validation error for AssetMeta
identifier
  field required (type=value_error.missing)

sub-an064/sub-an064_ses-20150214_obj-1uq8gph.nwb
Traceback (most recent call last):
  File "tools/populate_dandiset_asset_yamls.py", line 59, in main
    AssetMeta(**metadata)
  File "pydantic/main.py", line 362, in pydantic.main.BaseModel.__init__
pydantic.error_wrappers.ValidationError: 1 validation error for AssetMeta
identifier
  field required (type=value_error.missing)

sub-an064/sub-an064_ses-20150214_obj-4lo4te.nwb
Traceback (most recent call last):
  File "tools/populate_dandiset_asset_yamls.py", line 59, in main
    AssetMeta(**metadata)
  File "pydantic/main.py", line 362, in pydantic.main.BaseModel.__init__
pydantic.error_wrappers.ValidationError: 1 validation error for AssetMeta
identifier
  field required (type=value_error.missing)

sub-an064/sub-an064_ses-20150214_obj-73aw2e.nwb
Traceback (most recent call last):
  File "tools/populate_dandiset_asset_yamls.py", line 59, in main
    AssetMeta(**metadata)
  File "pydantic/main.py", line 362, in pydantic.main.BaseModel.__init__
pydantic.error_wrappers.ValidationError: 1 validation error for AssetMeta
identifier
  field required (type=value_error.missing)

sub-an064/sub-an064_ses-20150214_obj-m0p9h2.nwb
Traceback (most recent call last):
  File "tools/populate_dandiset_asset_yamls.py", line 59, in main
    AssetMeta(**metadata)
  File "pydantic/main.py", line 362, in pydantic.main.BaseModel.__init__
pydantic.error_wrappers.ValidationError: 1 validation error for AssetMeta
identifier
  field required (type=value_error.missing)

sub-an064/sub-an064_ses-20150214_obj-m80g1l.nwb
Traceback (most recent call last):
  File "tools/populate_dandiset_asset_yamls.py", line 59, in main
    AssetMeta(**metadata)
  File "pydantic/main.py", line 362, in pydantic.main.BaseModel.__init__
pydantic.error_wrappers.ValidationError: 1 validation error for AssetMeta
identifier
  field required (type=value_error.missing)

sub-an064/sub-an064_ses-20150214_obj-sgph6u.nwb
Traceback (most recent call last):
  File "tools/populate_dandiset_asset_yamls.py", line 59, in main
    AssetMeta(**metadata)
  File "pydantic/main.py", line 362, in pydantic.main.BaseModel.__init__
pydantic.error_wrappers.ValidationError: 1 validation error for AssetMeta
identifier
  field required (type=value_error.missing)

sub-an064/sub-an064_ses-20150214_obj-tkzaq9.nwb
Traceback (most recent call last):
  File "tools/populate_dandiset_asset_yamls.py", line 59, in main
    AssetMeta(**metadata)
  File "pydantic/main.py", line 362, in pydantic.main.BaseModel.__init__
pydantic.error_wrappers.ValidationError: 1 validation error for AssetMeta
identifier
  field required (type=value_error.missing)

sub-an064/sub-an064_ses-20150215_obj-13n6cgr.nwb
Traceback (most recent call last):
  File "tools/populate_dandiset_asset_yamls.py", line 59, in main
    AssetMeta(**metadata)
  File "pydantic/main.py", line 362, in pydantic.main.BaseModel.__init__
pydantic.error_wrappers.ValidationError: 1 validation error for AssetMeta
identifier
  field required (type=value_error.missing)

sub-an064/sub-an064_ses-20150215_obj-14nk5c6.nwb
Traceback (most recent call last):
  File "tools/populate_dandiset_asset_yamls.py", line 59, in main
    AssetMeta(**metadata)
  File "pydantic/main.py", line 362, in pydantic.main.BaseModel.__init__
pydantic.error_wrappers.ValidationError: 1 validation error for AssetMeta
identifier
  field required (type=value_error.missing)

sub-an064/sub-an064_ses-20150215_obj-1hxj4v2.nwb
Traceback (most recent call last):
  File "tools/populate_dandiset_asset_yamls.py", line 59, in main
    AssetMeta(**metadata)
  File "pydantic/main.py", line 362, in pydantic.main.BaseModel.__init__
pydantic.error_wrappers.ValidationError: 1 validation error for AssetMeta
identifier
  field required (type=value_error.missing)

sub-an064/sub-an064_ses-20150215_obj-1qo84eo.nwb
Traceback (most recent call last):
  File "tools/populate_dandiset_asset_yamls.py", line 59, in main
    AssetMeta(**metadata)
  File "pydantic/main.py", line 362, in pydantic.main.BaseModel.__init__
pydantic.error_wrappers.ValidationError: 1 validation error for AssetMeta
identifier
  field required (type=value_error.missing)

sub-an064/sub-an064_ses-20150215_obj-1tihbq0.nwb
Traceback (most recent call last):
  File "tools/populate_dandiset_asset_yamls.py", line 59, in main
    AssetMeta(**metadata)
  File "pydantic/main.py", line 362, in pydantic.main.BaseModel.__init__
pydantic.error_wrappers.ValidationError: 1 validation error for AssetMeta
identifier
  field required (type=value_error.missing)

sub-an064/sub-an064_ses-20150215_obj-1y6uoix.nwb
Traceback (most recent call last):
  File "tools/populate_dandiset_asset_yamls.py", line 59, in main
    AssetMeta(**metadata)
  File "pydantic/main.py", line 362, in pydantic.main.BaseModel.__init__
pydantic.error_wrappers.ValidationError: 1 validation error for AssetMeta
identifier
  field required (type=value_error.missing)

sub-an064/sub-an064_ses-20150215_obj-2gb5dd.nwb
Traceback (most recent call last):
  File "tools/populate_dandiset_asset_yamls.py", line 59, in main
    AssetMeta(**metadata)
  File "pydantic/main.py", line 362, in pydantic.main.BaseModel.__init__
pydantic.error_wrappers.ValidationError: 1 validation error for AssetMeta
identifier
  field required (type=value_error.missing)

sub-an064/sub-an064_ses-20150215_obj-3kkm1e.nwb
Traceback (most recent call last):
  File "tools/populate_dandiset_asset_yamls.py", line 59, in main
    AssetMeta(**metadata)
  File "pydantic/main.py", line 362, in pydantic.main.BaseModel.__init__
pydantic.error_wrappers.ValidationError: 1 validation error for AssetMeta
identifier
  field required (type=value_error.missing)

sub-an064/sub-an064_ses-20150215_obj-ply14z.nwb
Traceback (most recent call last):
  File "tools/populate_dandiset_asset_yamls.py", line 59, in main
    AssetMeta(**metadata)
  File "pydantic/main.py", line 362, in pydantic.main.BaseModel.__init__
pydantic.error_wrappers.ValidationError: 1 validation error for AssetMeta
identifier
  field required (type=value_error.missing)

sub-an064/sub-an064_ses-20150215_obj-xwwd89.nwb
Traceback (most recent call last):
  File "tools/populate_dandiset_asset_yamls.py", line 59, in main
    AssetMeta(**metadata)
  File "pydantic/main.py", line 362, in pydantic.main.BaseModel.__init__
pydantic.error_wrappers.ValidationError: 1 validation error for AssetMeta
identifier
  field required (type=value_error.missing)

sub-an064/sub-an064_ses-20150217_obj-13djtqs.nwb
Traceback (most recent call last):
  File "tools/populate_dandiset_asset_yamls.py", line 59, in main
    AssetMeta(**metadata)
  File "pydantic/main.py", line 362, in pydantic.main.BaseModel.__init__
pydantic.error_wrappers.ValidationError: 1 validation error for AssetMeta
identifier
  field required (type=value_error.missing)

sub-an064/sub-an064_ses-20150217_obj-1oad954.nwb
Traceback (most recent call last):
  File "tools/populate_dandiset_asset_yamls.py", line 59, in main
    AssetMeta(**metadata)
  File "pydantic/main.py", line 362, in pydantic.main.BaseModel.__init__
pydantic.error_wrappers.ValidationError: 1 validation error for AssetMeta
identifier
  field required (type=value_error.missing)

sub-an064/sub-an064_ses-20150217_obj-3i7d54.nwb
Traceback (most recent call last):
  File "tools/populate_dandiset_asset_yamls.py", line 59, in main
    AssetMeta(**metadata)
  File "pydantic/main.py", line 362, in pydantic.main.BaseModel.__init__
pydantic.error_wrappers.ValidationError: 1 validation error for AssetMeta
identifier
  field required (type=value_error.missing)

sub-an064/sub-an064_ses-20150217_obj-tjo18o.nwb
Traceback (most recent call last):
  File "tools/populate_dandiset_asset_yamls.py", line 59, in main
    AssetMeta(**metadata)
  File "pydantic/main.py", line 362, in pydantic.main.BaseModel.__init__
pydantic.error_wrappers.ValidationError: 1 validation error for AssetMeta
identifier
  field required (type=value_error.missing)

sub-an064/sub-an064_ses-20150217_obj-uznjlg.nwb
Traceback (most recent call last):
  File "tools/populate_dandiset_asset_yamls.py", line 59, in main
    AssetMeta(**metadata)
  File "pydantic/main.py", line 362, in pydantic.main.BaseModel.__init__
pydantic.error_wrappers.ValidationError: 1 validation error for AssetMeta
identifier
  field required (type=value_error.missing)

sub-an064/sub-an064_ses-20150217_obj-v260n7.nwb
Traceback (most recent call last):
  File "tools/populate_dandiset_asset_yamls.py", line 59, in main
    AssetMeta(**metadata)
  File "pydantic/main.py", line 362, in pydantic.main.BaseModel.__init__
pydantic.error_wrappers.ValidationError: 1 validation error for AssetMeta
identifier
  field required (type=value_error.missing)

sub-an064/sub-an064_ses-20150219_obj-13qmtvu.nwb
Traceback (most recent call last):
  File "tools/populate_dandiset_asset_yamls.py", line 59, in main
    AssetMeta(**metadata)
  File "pydantic/main.py", line 362, in pydantic.main.BaseModel.__init__
pydantic.error_wrappers.ValidationError: 1 validation error for AssetMeta
identifier
  field required (type=value_error.missing)

sub-an064/sub-an064_ses-20150219_obj-18v1u0u.nwb
Traceback (most recent call last):
  File "tools/populate_dandiset_asset_yamls.py", line 59, in main
    AssetMeta(**metadata)
  File "pydantic/main.py", line 362, in pydantic.main.BaseModel.__init__
pydantic.error_wrappers.ValidationError: 1 validation error for AssetMeta
identifier
  field required (type=value_error.missing)

sub-an064/sub-an064_ses-20150219_obj-1bs8vhv.nwb
Traceback (most recent call last):
  File "tools/populate_dandiset_asset_yamls.py", line 59, in main
    AssetMeta(**metadata)
  File "pydantic/main.py", line 362, in pydantic.main.BaseModel.__init__
pydantic.error_wrappers.ValidationError: 1 validation error for AssetMeta
identifier
  field required (type=value_error.missing)

sub-an064/sub-an064_ses-20150219_obj-hid9x0.nwb
Traceback (most recent call last):
  File "tools/populate_dandiset_asset_yamls.py", line 59, in main
    AssetMeta(**metadata)
  File "pydantic/main.py", line 362, in pydantic.main.BaseModel.__init__
pydantic.error_wrappers.ValidationError: 1 validation error for AssetMeta
identifier
  field required (type=value_error.missing)

sub-an064/sub-an064_ses-20150219_obj-o0oo82.nwb
Traceback (most recent call last):
  File "tools/populate_dandiset_asset_yamls.py", line 59, in main
    AssetMeta(**metadata)
  File "pydantic/main.py", line 362, in pydantic.main.BaseModel.__init__
pydantic.error_wrappers.ValidationError: 1 validation error for AssetMeta
identifier
  field required (type=value_error.missing)

sub-an064/sub-an064_ses-20150219_obj-zy8v7t.nwb
Traceback (most recent call last):
  File "tools/populate_dandiset_asset_yamls.py", line 59, in main
    AssetMeta(**metadata)
  File "pydantic/main.py", line 362, in pydantic.main.BaseModel.__init__
pydantic.error_wrappers.ValidationError: 1 validation error for AssetMeta
identifier
  field required (type=value_error.missing)

sub-an066/sub-an066_ses-20150205_obj-1dwc8hk.nwb
Traceback (most recent call last):
  File "tools/populate_dandiset_asset_yamls.py", line 59, in main
    AssetMeta(**metadata)
  File "pydantic/main.py", line 362, in pydantic.main.BaseModel.__init__
pydantic.error_wrappers.ValidationError: 1 validation error for AssetMeta
identifier
  field required (type=value_error.missing)

sub-an066/sub-an066_ses-20150205_obj-1oq8r0h.nwb
Traceback (most recent call last):
  File "tools/populate_dandiset_asset_yamls.py", line 59, in main
    AssetMeta(**metadata)
  File "pydantic/main.py", line 362, in pydantic.main.BaseModel.__init__
pydantic.error_wrappers.ValidationError: 1 validation error for AssetMeta
identifier
  field required (type=value_error.missing)

sub-an066/sub-an066_ses-20150206_obj-10arvlt.nwb
Traceback (most recent call last):
  File "tools/populate_dandiset_asset_yamls.py", line 59, in main
    AssetMeta(**metadata)
  File "pydantic/main.py", line 362, in pydantic.main.BaseModel.__init__
pydantic.error_wrappers.ValidationError: 1 validation error for AssetMeta
identifier
  field required (type=value_error.missing)

sub-an066/sub-an066_ses-20150206_obj-16dlnt9.nwb
Traceback (most recent call last):
  File "tools/populate_dandiset_asset_yamls.py", line 59, in main
    AssetMeta(**metadata)
  File "pydantic/main.py", line 362, in pydantic.main.BaseModel.__init__
pydantic.error_wrappers.ValidationError: 1 validation error for AssetMeta
identifier
  field required (type=value_error.missing)

sub-an066/sub-an066_ses-20150206_obj-1aavzhx.nwb
Traceback (most recent call last):
  File "tools/populate_dandiset_asset_yamls.py", line 59, in main
    AssetMeta(**metadata)
  File "pydantic/main.py", line 362, in pydantic.main.BaseModel.__init__
pydantic.error_wrappers.ValidationError: 1 validation error for AssetMeta
identifier
  field required (type=value_error.missing)

sub-an066/sub-an066_ses-20150206_obj-1mu1jmc.nwb
Traceback (most recent call last):
  File "tools/populate_dandiset_asset_yamls.py", line 59, in main
    AssetMeta(**metadata)
  File "pydantic/main.py", line 362, in pydantic.main.BaseModel.__init__
pydantic.error_wrappers.ValidationError: 1 validation error for AssetMeta
identifier
  field required (type=value_error.missing)

sub-an066/sub-an066_ses-20150206_obj-1suwa9k.nwb
Traceback (most recent call last):
  File "tools/populate_dandiset_asset_yamls.py", line 59, in main
    AssetMeta(**metadata)
  File "pydantic/main.py", line 362, in pydantic.main.BaseModel.__init__
pydantic.error_wrappers.ValidationError: 1 validation error for AssetMeta
identifier
  field required (type=value_error.missing)

sub-an066/sub-an066_ses-20150206_obj-52hco0.nwb
Traceback (most recent call last):
  File "tools/populate_dandiset_asset_yamls.py", line 59, in main
    AssetMeta(**metadata)
  File "pydantic/main.py", line 362, in pydantic.main.BaseModel.__init__
pydantic.error_wrappers.ValidationError: 1 validation error for AssetMeta
identifier
  field required (type=value_error.missing)

sub-an066/sub-an066_ses-20150206_obj-d6420e.nwb
Traceback (most recent call last):
  File "tools/populate_dandiset_asset_yamls.py", line 59, in main
    AssetMeta(**metadata)
  File "pydantic/main.py", line 362, in pydantic.main.BaseModel.__init__
pydantic.error_wrappers.ValidationError: 1 validation error for AssetMeta
identifier
  field required (type=value_error.missing)

sub-an066/sub-an066_ses-20150206_obj-m7h1bm.nwb
Traceback (most recent call last):
  File "tools/populate_dandiset_asset_yamls.py", line 59, in main
    AssetMeta(**metadata)
  File "pydantic/main.py", line 362, in pydantic.main.BaseModel.__init__
pydantic.error_wrappers.ValidationError: 1 validation error for AssetMeta
identifier
  field required (type=value_error.missing)

sub-an066/sub-an066_ses-20150211_obj-1j0mnta.nwb
Traceback (most recent call last):
  File "tools/populate_dandiset_asset_yamls.py", line 59, in main
    AssetMeta(**metadata)
  File "pydantic/main.py", line 362, in pydantic.main.BaseModel.__init__
pydantic.error_wrappers.ValidationError: 1 validation error for AssetMeta
identifier
  field required (type=value_error.missing)

sub-an066/sub-an066_ses-20150211_obj-1uyc237.nwb
Traceback (most recent call last):
  File "tools/populate_dandiset_asset_yamls.py", line 59, in main
    AssetMeta(**metadata)
  File "pydantic/main.py", line 362, in pydantic.main.BaseModel.__init__
pydantic.error_wrappers.ValidationError: 1 validation error for AssetMeta
identifier
  field required (type=value_error.missing)

sub-an066/sub-an066_ses-20150211_obj-f0ajmr.nwb
Traceback (most recent call last):
  File "tools/populate_dandiset_asset_yamls.py", line 59, in main
    AssetMeta(**metadata)
  File "pydantic/main.py", line 362, in pydantic.main.BaseModel.__init__
pydantic.error_wrappers.ValidationError: 1 validation error for AssetMeta
identifier
  field required (type=value_error.missing)

sub-an066/sub-an066_ses-20150211_obj-hssdpk.nwb
Traceback (most recent call last):
  File "tools/populate_dandiset_asset_yamls.py", line 59, in main
    AssetMeta(**metadata)
  File "pydantic/main.py", line 362, in pydantic.main.BaseModel.__init__
pydantic.error_wrappers.ValidationError: 1 validation error for AssetMeta
identifier
  field required (type=value_error.missing)

