sub-Achilles/sub-Achilles_ses-Achilles-10252013_behavior+ecephys.nwb
Traceback (most recent call last):
  File "tools/populate_dandiset_asset_yamls.py", line 73, in main
    AssetMeta(**metadata)
  File "pydantic/main.py", line 362, in pydantic.main.BaseModel.__init__
pydantic.error_wrappers.ValidationError: 1 validation error for AssetMeta
identifier
  field required (type=value_error.missing)

sub-Achilles/sub-Achilles_ses-Achilles-11012013_behavior+ecephys.nwb
Traceback (most recent call last):
  File "tools/populate_dandiset_asset_yamls.py", line 73, in main
    AssetMeta(**metadata)
  File "pydantic/main.py", line 362, in pydantic.main.BaseModel.__init__
pydantic.error_wrappers.ValidationError: 1 validation error for AssetMeta
identifier
  field required (type=value_error.missing)

sub-Buddy/sub-Buddy_ses-Buddy-06272013_behavior+ecephys.nwb
Traceback (most recent call last):
  File "tools/populate_dandiset_asset_yamls.py", line 73, in main
    AssetMeta(**metadata)
  File "pydantic/main.py", line 362, in pydantic.main.BaseModel.__init__
pydantic.error_wrappers.ValidationError: 1 validation error for AssetMeta
identifier
  field required (type=value_error.missing)

sub-Cicero/sub-Cicero_ses-Cicero-09012014_behavior+ecephys.nwb
Traceback (most recent call last):
  File "tools/populate_dandiset_asset_yamls.py", line 73, in main
    AssetMeta(**metadata)
  File "pydantic/main.py", line 362, in pydantic.main.BaseModel.__init__
pydantic.error_wrappers.ValidationError: 1 validation error for AssetMeta
identifier
  field required (type=value_error.missing)

sub-Cicero/sub-Cicero_ses-Cicero-09102014_behavior+ecephys.nwb
Traceback (most recent call last):
  File "tools/populate_dandiset_asset_yamls.py", line 73, in main
    AssetMeta(**metadata)
  File "pydantic/main.py", line 362, in pydantic.main.BaseModel.__init__
pydantic.error_wrappers.ValidationError: 1 validation error for AssetMeta
identifier
  field required (type=value_error.missing)

sub-Cicero/sub-Cicero_ses-Cicero-09172014_behavior+ecephys.nwb
Traceback (most recent call last):
  File "tools/populate_dandiset_asset_yamls.py", line 73, in main
    AssetMeta(**metadata)
  File "pydantic/main.py", line 362, in pydantic.main.BaseModel.__init__
pydantic.error_wrappers.ValidationError: 1 validation error for AssetMeta
identifier
  field required (type=value_error.missing)

sub-Gatsby/sub-Gatsby_ses-Gatsby-08022013_behavior+ecephys.nwb
Traceback (most recent call last):
  File "tools/populate_dandiset_asset_yamls.py", line 73, in main
    AssetMeta(**metadata)
  File "pydantic/main.py", line 362, in pydantic.main.BaseModel.__init__
pydantic.error_wrappers.ValidationError: 1 validation error for AssetMeta
identifier
  field required (type=value_error.missing)

sub-Gatsby/sub-Gatsby_ses-Gatsby-08282013_behavior+ecephys.nwb
Traceback (most recent call last):
  File "tools/populate_dandiset_asset_yamls.py", line 73, in main
    AssetMeta(**metadata)
  File "pydantic/main.py", line 362, in pydantic.main.BaseModel.__init__
pydantic.error_wrappers.ValidationError: 1 validation error for AssetMeta
identifier
  field required (type=value_error.missing)

