sub-R1/sub-R1_ses-20190209T210000_obj-1n02f81_behavior+ophys.nwb
Traceback (most recent call last):
  File "tools/populate_dandiset_asset_yamls.py", line 73, in main
    AssetMeta(**metadata)
  File "pydantic/main.py", line 362, in pydantic.main.BaseModel.__init__
pydantic.error_wrappers.ValidationError: 1 validation error for AssetMeta
identifier
  field required (type=value_error.missing)

sub-R1/sub-R1_ses-20190209T210000_obj-b2dqyv_behavior+ophys.nwb
Traceback (most recent call last):
  File "tools/populate_dandiset_asset_yamls.py", line 73, in main
    AssetMeta(**metadata)
  File "pydantic/main.py", line 362, in pydantic.main.BaseModel.__init__
pydantic.error_wrappers.ValidationError: 1 validation error for AssetMeta
identifier
  field required (type=value_error.missing)

sub-R1/sub-R1_ses-20190211T210000_behavior+ophys.nwb
Traceback (most recent call last):
  File "tools/populate_dandiset_asset_yamls.py", line 73, in main
    AssetMeta(**metadata)
  File "pydantic/main.py", line 362, in pydantic.main.BaseModel.__init__
pydantic.error_wrappers.ValidationError: 1 validation error for AssetMeta
identifier
  field required (type=value_error.missing)

sub-R1/sub-R1_ses-20190214T210000_behavior+ophys.nwb
Traceback (most recent call last):
  File "tools/populate_dandiset_asset_yamls.py", line 73, in main
    AssetMeta(**metadata)
  File "pydantic/main.py", line 362, in pydantic.main.BaseModel.__init__
pydantic.error_wrappers.ValidationError: 1 validation error for AssetMeta
identifier
  field required (type=value_error.missing)

sub-R1/sub-R1_ses-20190216T210000_behavior+ophys.nwb
Traceback (most recent call last):
  File "tools/populate_dandiset_asset_yamls.py", line 73, in main
    AssetMeta(**metadata)
  File "pydantic/main.py", line 362, in pydantic.main.BaseModel.__init__
pydantic.error_wrappers.ValidationError: 1 validation error for AssetMeta
identifier
  field required (type=value_error.missing)

sub-R1/sub-R1_ses-20190218T210000_behavior+ophys.nwb
Traceback (most recent call last):
  File "tools/populate_dandiset_asset_yamls.py", line 73, in main
    AssetMeta(**metadata)
  File "pydantic/main.py", line 362, in pydantic.main.BaseModel.__init__
pydantic.error_wrappers.ValidationError: 1 validation error for AssetMeta
identifier
  field required (type=value_error.missing)

sub-R1/sub-R1_ses-20190220T210000_behavior+ophys.nwb
Traceback (most recent call last):
  File "tools/populate_dandiset_asset_yamls.py", line 73, in main
    AssetMeta(**metadata)
  File "pydantic/main.py", line 362, in pydantic.main.BaseModel.__init__
pydantic.error_wrappers.ValidationError: 1 validation error for AssetMeta
identifier
  field required (type=value_error.missing)

sub-R1/sub-R1_ses-20190221T210000_behavior+ophys.nwb
Traceback (most recent call last):
  File "tools/populate_dandiset_asset_yamls.py", line 73, in main
    AssetMeta(**metadata)
  File "pydantic/main.py", line 362, in pydantic.main.BaseModel.__init__
pydantic.error_wrappers.ValidationError: 1 validation error for AssetMeta
identifier
  field required (type=value_error.missing)

sub-R1/sub-R1_ses-20190222T210000_behavior+ophys.nwb
Traceback (most recent call last):
  File "tools/populate_dandiset_asset_yamls.py", line 73, in main
    AssetMeta(**metadata)
  File "pydantic/main.py", line 362, in pydantic.main.BaseModel.__init__
pydantic.error_wrappers.ValidationError: 1 validation error for AssetMeta
identifier
  field required (type=value_error.missing)

sub-R1/sub-R1_ses-20190223T210000_behavior+ophys.nwb
Traceback (most recent call last):
  File "tools/populate_dandiset_asset_yamls.py", line 73, in main
    AssetMeta(**metadata)
  File "pydantic/main.py", line 362, in pydantic.main.BaseModel.__init__
pydantic.error_wrappers.ValidationError: 1 validation error for AssetMeta
identifier
  field required (type=value_error.missing)

sub-R2/sub-R2_ses-20190206T210000_obj-rlev12_behavior+ophys.nwb
Traceback (most recent call last):
  File "tools/populate_dandiset_asset_yamls.py", line 73, in main
    AssetMeta(**metadata)
  File "pydantic/main.py", line 362, in pydantic.main.BaseModel.__init__
pydantic.error_wrappers.ValidationError: 1 validation error for AssetMeta
identifier
  field required (type=value_error.missing)

sub-R2/sub-R2_ses-20190206T210000_obj-vvyqhx_behavior+ophys.nwb
Traceback (most recent call last):
  File "tools/populate_dandiset_asset_yamls.py", line 73, in main
    AssetMeta(**metadata)
  File "pydantic/main.py", line 362, in pydantic.main.BaseModel.__init__
pydantic.error_wrappers.ValidationError: 1 validation error for AssetMeta
identifier
  field required (type=value_error.missing)

sub-R2/sub-R2_ses-20190209T210000_behavior+ophys.nwb
Traceback (most recent call last):
  File "tools/populate_dandiset_asset_yamls.py", line 73, in main
    AssetMeta(**metadata)
  File "pydantic/main.py", line 362, in pydantic.main.BaseModel.__init__
pydantic.error_wrappers.ValidationError: 1 validation error for AssetMeta
identifier
  field required (type=value_error.missing)

sub-R2/sub-R2_ses-20190211T210000_behavior+ophys.nwb
Traceback (most recent call last):
  File "tools/populate_dandiset_asset_yamls.py", line 73, in main
    AssetMeta(**metadata)
  File "pydantic/main.py", line 362, in pydantic.main.BaseModel.__init__
pydantic.error_wrappers.ValidationError: 1 validation error for AssetMeta
identifier
  field required (type=value_error.missing)

sub-R2/sub-R2_ses-20190214T210000_behavior+ophys.nwb
Traceback (most recent call last):
  File "tools/populate_dandiset_asset_yamls.py", line 73, in main
    AssetMeta(**metadata)
  File "pydantic/main.py", line 362, in pydantic.main.BaseModel.__init__
pydantic.error_wrappers.ValidationError: 1 validation error for AssetMeta
identifier
  field required (type=value_error.missing)

sub-R2/sub-R2_ses-20190216T210000_behavior+ophys.nwb
Traceback (most recent call last):
  File "tools/populate_dandiset_asset_yamls.py", line 73, in main
    AssetMeta(**metadata)
  File "pydantic/main.py", line 362, in pydantic.main.BaseModel.__init__
pydantic.error_wrappers.ValidationError: 1 validation error for AssetMeta
identifier
  field required (type=value_error.missing)

sub-R2/sub-R2_ses-20190217T210000_behavior+ophys.nwb
Traceback (most recent call last):
  File "tools/populate_dandiset_asset_yamls.py", line 73, in main
    AssetMeta(**metadata)
  File "pydantic/main.py", line 362, in pydantic.main.BaseModel.__init__
pydantic.error_wrappers.ValidationError: 1 validation error for AssetMeta
identifier
  field required (type=value_error.missing)

sub-R2/sub-R2_ses-20190218T210000_behavior+ophys.nwb
Traceback (most recent call last):
  File "tools/populate_dandiset_asset_yamls.py", line 73, in main
    AssetMeta(**metadata)
  File "pydantic/main.py", line 362, in pydantic.main.BaseModel.__init__
pydantic.error_wrappers.ValidationError: 1 validation error for AssetMeta
identifier
  field required (type=value_error.missing)

sub-R2/sub-R2_ses-20190219T210000_behavior+ophys.nwb
Traceback (most recent call last):
  File "tools/populate_dandiset_asset_yamls.py", line 73, in main
    AssetMeta(**metadata)
  File "pydantic/main.py", line 362, in pydantic.main.BaseModel.__init__
pydantic.error_wrappers.ValidationError: 1 validation error for AssetMeta
identifier
  field required (type=value_error.missing)

sub-R2/sub-R2_ses-20190220T210000_behavior+ophys.nwb
Traceback (most recent call last):
  File "tools/populate_dandiset_asset_yamls.py", line 73, in main
    AssetMeta(**metadata)
  File "pydantic/main.py", line 362, in pydantic.main.BaseModel.__init__
pydantic.error_wrappers.ValidationError: 1 validation error for AssetMeta
identifier
  field required (type=value_error.missing)

sub-R3/sub-R3_ses-20190209T210000_obj-1rv5g5y_behavior+ophys.nwb
Traceback (most recent call last):
  File "tools/populate_dandiset_asset_yamls.py", line 73, in main
    AssetMeta(**metadata)
  File "pydantic/main.py", line 362, in pydantic.main.BaseModel.__init__
pydantic.error_wrappers.ValidationError: 1 validation error for AssetMeta
identifier
  field required (type=value_error.missing)

sub-R3/sub-R3_ses-20190209T210000_obj-7qcre5_behavior+ophys.nwb
Traceback (most recent call last):
  File "tools/populate_dandiset_asset_yamls.py", line 73, in main
    AssetMeta(**metadata)
  File "pydantic/main.py", line 362, in pydantic.main.BaseModel.__init__
pydantic.error_wrappers.ValidationError: 1 validation error for AssetMeta
identifier
  field required (type=value_error.missing)

sub-R3/sub-R3_ses-20190211T210000_behavior+ophys.nwb
Traceback (most recent call last):
  File "tools/populate_dandiset_asset_yamls.py", line 73, in main
    AssetMeta(**metadata)
  File "pydantic/main.py", line 362, in pydantic.main.BaseModel.__init__
pydantic.error_wrappers.ValidationError: 1 validation error for AssetMeta
identifier
  field required (type=value_error.missing)

sub-R3/sub-R3_ses-20190214T210000_behavior+ophys.nwb
Traceback (most recent call last):
  File "tools/populate_dandiset_asset_yamls.py", line 73, in main
    AssetMeta(**metadata)
  File "pydantic/main.py", line 362, in pydantic.main.BaseModel.__init__
pydantic.error_wrappers.ValidationError: 1 validation error for AssetMeta
identifier
  field required (type=value_error.missing)

sub-R3/sub-R3_ses-20190216T210000_behavior+ophys.nwb
Traceback (most recent call last):
  File "tools/populate_dandiset_asset_yamls.py", line 73, in main
    AssetMeta(**metadata)
  File "pydantic/main.py", line 362, in pydantic.main.BaseModel.__init__
pydantic.error_wrappers.ValidationError: 1 validation error for AssetMeta
identifier
  field required (type=value_error.missing)

sub-R3/sub-R3_ses-20190218T210000_behavior+ophys.nwb
Traceback (most recent call last):
  File "tools/populate_dandiset_asset_yamls.py", line 73, in main
    AssetMeta(**metadata)
  File "pydantic/main.py", line 362, in pydantic.main.BaseModel.__init__
pydantic.error_wrappers.ValidationError: 1 validation error for AssetMeta
identifier
  field required (type=value_error.missing)

sub-R3/sub-R3_ses-20190220T210000_behavior+ophys.nwb
Traceback (most recent call last):
  File "tools/populate_dandiset_asset_yamls.py", line 73, in main
    AssetMeta(**metadata)
  File "pydantic/main.py", line 362, in pydantic.main.BaseModel.__init__
pydantic.error_wrappers.ValidationError: 1 validation error for AssetMeta
identifier
  field required (type=value_error.missing)

sub-R3/sub-R3_ses-20190221T210000_behavior+ophys.nwb
Traceback (most recent call last):
  File "tools/populate_dandiset_asset_yamls.py", line 73, in main
    AssetMeta(**metadata)
  File "pydantic/main.py", line 362, in pydantic.main.BaseModel.__init__
pydantic.error_wrappers.ValidationError: 1 validation error for AssetMeta
identifier
  field required (type=value_error.missing)

sub-R3/sub-R3_ses-20190222T210000_behavior+ophys.nwb
Traceback (most recent call last):
  File "tools/populate_dandiset_asset_yamls.py", line 73, in main
    AssetMeta(**metadata)
  File "pydantic/main.py", line 362, in pydantic.main.BaseModel.__init__
pydantic.error_wrappers.ValidationError: 1 validation error for AssetMeta
identifier
  field required (type=value_error.missing)

sub-R3/sub-R3_ses-20190223T210000_behavior+ophys.nwb
Traceback (most recent call last):
  File "tools/populate_dandiset_asset_yamls.py", line 73, in main
    AssetMeta(**metadata)
  File "pydantic/main.py", line 362, in pydantic.main.BaseModel.__init__
pydantic.error_wrappers.ValidationError: 1 validation error for AssetMeta
identifier
  field required (type=value_error.missing)

