sub-Bogey/sub-Bogey_ses-Bogey-012615_ecephys.nwb
Traceback (most recent call last):
  File "tools/populate_dandiset_asset_yamls.py", line 59, in main
    AssetMeta(**metadata)
  File "pydantic/main.py", line 362, in pydantic.main.BaseModel.__init__
pydantic.error_wrappers.ValidationError: 1 validation error for AssetMeta
identifier
  field required (type=value_error.missing)

sub-BWRat17/sub-BWRat17_ses-BWRat17-121712_ecephys.nwb
Traceback (most recent call last):
  File "tools/populate_dandiset_asset_yamls.py", line 59, in main
    AssetMeta(**metadata)
  File "pydantic/main.py", line 362, in pydantic.main.BaseModel.__init__
pydantic.error_wrappers.ValidationError: 1 validation error for AssetMeta
identifier
  field required (type=value_error.missing)

sub-BWRat17/sub-BWRat17_ses-BWRat17-121912_ecephys.nwb
Traceback (most recent call last):
  File "tools/populate_dandiset_asset_yamls.py", line 59, in main
    AssetMeta(**metadata)
  File "pydantic/main.py", line 362, in pydantic.main.BaseModel.__init__
pydantic.error_wrappers.ValidationError: 1 validation error for AssetMeta
identifier
  field required (type=value_error.missing)

sub-BWRat18/sub-BWRat18_ses-BWRat18-020513_ecephys.nwb
Traceback (most recent call last):
  File "tools/populate_dandiset_asset_yamls.py", line 59, in main
    AssetMeta(**metadata)
  File "pydantic/main.py", line 362, in pydantic.main.BaseModel.__init__
pydantic.error_wrappers.ValidationError: 1 validation error for AssetMeta
identifier
  field required (type=value_error.missing)

sub-BWRat19/sub-BWRat19_ses-BWRat19-032413_ecephys.nwb
Traceback (most recent call last):
  File "tools/populate_dandiset_asset_yamls.py", line 59, in main
    AssetMeta(**metadata)
  File "pydantic/main.py", line 362, in pydantic.main.BaseModel.__init__
pydantic.error_wrappers.ValidationError: 1 validation error for AssetMeta
identifier
  field required (type=value_error.missing)

sub-BWRat19/sub-BWRat19_ses-BWRat19-032513_ecephys.nwb
Traceback (most recent call last):
  File "tools/populate_dandiset_asset_yamls.py", line 59, in main
    AssetMeta(**metadata)
  File "pydantic/main.py", line 362, in pydantic.main.BaseModel.__init__
pydantic.error_wrappers.ValidationError: 1 validation error for AssetMeta
identifier
  field required (type=value_error.missing)

sub-BWRat20/sub-BWRat20_ses-BWRat20-101013_ecephys.nwb
Traceback (most recent call last):
  File "tools/populate_dandiset_asset_yamls.py", line 59, in main
    AssetMeta(**metadata)
  File "pydantic/main.py", line 362, in pydantic.main.BaseModel.__init__
pydantic.error_wrappers.ValidationError: 1 validation error for AssetMeta
identifier
  field required (type=value_error.missing)

sub-BWRat20/sub-BWRat20_ses-BWRat20-101513_ecephys.nwb
Traceback (most recent call last):
  File "tools/populate_dandiset_asset_yamls.py", line 59, in main
    AssetMeta(**metadata)
  File "pydantic/main.py", line 362, in pydantic.main.BaseModel.__init__
pydantic.error_wrappers.ValidationError: 1 validation error for AssetMeta
identifier
  field required (type=value_error.missing)

sub-BWRat21/sub-BWRat21_ses-BWRat21-121113_ecephys.nwb
Traceback (most recent call last):
  File "tools/populate_dandiset_asset_yamls.py", line 59, in main
    AssetMeta(**metadata)
  File "pydantic/main.py", line 362, in pydantic.main.BaseModel.__init__
pydantic.error_wrappers.ValidationError: 1 validation error for AssetMeta
identifier
  field required (type=value_error.missing)

sub-BWRat21/sub-BWRat21_ses-BWRat21-121613_ecephys.nwb
Traceback (most recent call last):
  File "tools/populate_dandiset_asset_yamls.py", line 59, in main
    AssetMeta(**metadata)
  File "pydantic/main.py", line 362, in pydantic.main.BaseModel.__init__
pydantic.error_wrappers.ValidationError: 1 validation error for AssetMeta
identifier
  field required (type=value_error.missing)

sub-BWRat21/sub-BWRat21_ses-BWRat21-121813_ecephys.nwb
Traceback (most recent call last):
  File "tools/populate_dandiset_asset_yamls.py", line 59, in main
    AssetMeta(**metadata)
  File "pydantic/main.py", line 362, in pydantic.main.BaseModel.__init__
pydantic.error_wrappers.ValidationError: 1 validation error for AssetMeta
identifier
  field required (type=value_error.missing)

sub-Dino/sub-Dino_ses-Dino-061814_ecephys.nwb
Traceback (most recent call last):
  File "tools/populate_dandiset_asset_yamls.py", line 59, in main
    AssetMeta(**metadata)
  File "pydantic/main.py", line 362, in pydantic.main.BaseModel.__init__
pydantic.error_wrappers.ValidationError: 1 validation error for AssetMeta
identifier
  field required (type=value_error.missing)

sub-Dino/sub-Dino_ses-Dino-061914_ecephys.nwb
Traceback (most recent call last):
  File "tools/populate_dandiset_asset_yamls.py", line 59, in main
    AssetMeta(**metadata)
  File "pydantic/main.py", line 362, in pydantic.main.BaseModel.__init__
pydantic.error_wrappers.ValidationError: 1 validation error for AssetMeta
identifier
  field required (type=value_error.missing)

sub-Dino/sub-Dino_ses-Dino-062014_ecephys.nwb
Traceback (most recent call last):
  File "tools/populate_dandiset_asset_yamls.py", line 59, in main
    AssetMeta(**metadata)
  File "pydantic/main.py", line 362, in pydantic.main.BaseModel.__init__
pydantic.error_wrappers.ValidationError: 1 validation error for AssetMeta
identifier
  field required (type=value_error.missing)

sub-Dino/sub-Dino_ses-Dino-072114_ecephys.nwb
Traceback (most recent call last):
  File "tools/populate_dandiset_asset_yamls.py", line 59, in main
    AssetMeta(**metadata)
  File "pydantic/main.py", line 362, in pydantic.main.BaseModel.__init__
pydantic.error_wrappers.ValidationError: 1 validation error for AssetMeta
identifier
  field required (type=value_error.missing)

sub-Dino/sub-Dino_ses-Dino-072314_ecephys.nwb
Traceback (most recent call last):
  File "tools/populate_dandiset_asset_yamls.py", line 59, in main
    AssetMeta(**metadata)
  File "pydantic/main.py", line 362, in pydantic.main.BaseModel.__init__
pydantic.error_wrappers.ValidationError: 1 validation error for AssetMeta
identifier
  field required (type=value_error.missing)

sub-Dino/sub-Dino_ses-Dino-072414_ecephys.nwb
Traceback (most recent call last):
  File "tools/populate_dandiset_asset_yamls.py", line 59, in main
    AssetMeta(**metadata)
  File "pydantic/main.py", line 362, in pydantic.main.BaseModel.__init__
pydantic.error_wrappers.ValidationError: 1 validation error for AssetMeta
identifier
  field required (type=value_error.missing)

sub-Rizzo/sub-Rizzo_ses-Rizzo-022615_ecephys.nwb
Traceback (most recent call last):
  File "tools/populate_dandiset_asset_yamls.py", line 59, in main
    AssetMeta(**metadata)
  File "pydantic/main.py", line 362, in pydantic.main.BaseModel.__init__
pydantic.error_wrappers.ValidationError: 1 validation error for AssetMeta
identifier
  field required (type=value_error.missing)

sub-Rizzo/sub-Rizzo_ses-Rizzo-022715_ecephys.nwb
Traceback (most recent call last):
  File "tools/populate_dandiset_asset_yamls.py", line 59, in main
    AssetMeta(**metadata)
  File "pydantic/main.py", line 362, in pydantic.main.BaseModel.__init__
pydantic.error_wrappers.ValidationError: 1 validation error for AssetMeta
identifier
  field required (type=value_error.missing)

sub-Splinter/sub-Splinter_ses-Splinter-020515_ecephys.nwb
Traceback (most recent call last):
  File "tools/populate_dandiset_asset_yamls.py", line 59, in main
    AssetMeta(**metadata)
  File "pydantic/main.py", line 362, in pydantic.main.BaseModel.__init__
pydantic.error_wrappers.ValidationError: 1 validation error for AssetMeta
identifier
  field required (type=value_error.missing)

sub-Splinter/sub-Splinter_ses-Splinter-020915_ecephys.nwb
Traceback (most recent call last):
  File "tools/populate_dandiset_asset_yamls.py", line 59, in main
    AssetMeta(**metadata)
  File "pydantic/main.py", line 362, in pydantic.main.BaseModel.__init__
pydantic.error_wrappers.ValidationError: 1 validation error for AssetMeta
identifier
  field required (type=value_error.missing)

sub-Templeton/sub-Templeton_ses-Templeton-032415_ecephys.nwb
Traceback (most recent call last):
  File "tools/populate_dandiset_asset_yamls.py", line 59, in main
    AssetMeta(**metadata)
  File "pydantic/main.py", line 362, in pydantic.main.BaseModel.__init__
pydantic.error_wrappers.ValidationError: 1 validation error for AssetMeta
identifier
  field required (type=value_error.missing)

