sub-Cori/sub-Cori_ses-20161214T120000.nwb
Traceback (most recent call last):
  File "tools/populate_dandiset_asset_yamls.py", line 73, in main
    AssetMeta(**metadata)
  File "pydantic/main.py", line 362, in pydantic.main.BaseModel.__init__
pydantic.error_wrappers.ValidationError: 1 validation error for AssetMeta
identifier
  field required (type=value_error.missing)

sub-Cori/sub-Cori_ses-20161217T120000.nwb
Traceback (most recent call last):
  File "tools/populate_dandiset_asset_yamls.py", line 73, in main
    AssetMeta(**metadata)
  File "pydantic/main.py", line 362, in pydantic.main.BaseModel.__init__
pydantic.error_wrappers.ValidationError: 1 validation error for AssetMeta
identifier
  field required (type=value_error.missing)

sub-Cori/sub-Cori_ses-20161218T120000.nwb
Traceback (most recent call last):
  File "tools/populate_dandiset_asset_yamls.py", line 73, in main
    AssetMeta(**metadata)
  File "pydantic/main.py", line 362, in pydantic.main.BaseModel.__init__
pydantic.error_wrappers.ValidationError: 1 validation error for AssetMeta
identifier
  field required (type=value_error.missing)

sub-Forssmann/sub-Forssmann_ses-20171101T120000.nwb
Traceback (most recent call last):
  File "tools/populate_dandiset_asset_yamls.py", line 73, in main
    AssetMeta(**metadata)
  File "pydantic/main.py", line 362, in pydantic.main.BaseModel.__init__
pydantic.error_wrappers.ValidationError: 1 validation error for AssetMeta
identifier
  field required (type=value_error.missing)

sub-Forssmann/sub-Forssmann_ses-20171102T120000.nwb
Traceback (most recent call last):
  File "tools/populate_dandiset_asset_yamls.py", line 73, in main
    AssetMeta(**metadata)
  File "pydantic/main.py", line 362, in pydantic.main.BaseModel.__init__
pydantic.error_wrappers.ValidationError: 1 validation error for AssetMeta
identifier
  field required (type=value_error.missing)

sub-Forssmann/sub-Forssmann_ses-20171104T120000.nwb
Traceback (most recent call last):
  File "tools/populate_dandiset_asset_yamls.py", line 73, in main
    AssetMeta(**metadata)
  File "pydantic/main.py", line 362, in pydantic.main.BaseModel.__init__
pydantic.error_wrappers.ValidationError: 1 validation error for AssetMeta
identifier
  field required (type=value_error.missing)

sub-Forssmann/sub-Forssmann_ses-20171105T120000.nwb
Traceback (most recent call last):
  File "tools/populate_dandiset_asset_yamls.py", line 73, in main
    AssetMeta(**metadata)
  File "pydantic/main.py", line 362, in pydantic.main.BaseModel.__init__
pydantic.error_wrappers.ValidationError: 1 validation error for AssetMeta
identifier
  field required (type=value_error.missing)

sub-Hench/sub-Hench_ses-20170615T120000.nwb
Traceback (most recent call last):
  File "tools/populate_dandiset_asset_yamls.py", line 73, in main
    AssetMeta(**metadata)
  File "pydantic/main.py", line 362, in pydantic.main.BaseModel.__init__
pydantic.error_wrappers.ValidationError: 1 validation error for AssetMeta
identifier
  field required (type=value_error.missing)

sub-Hench/sub-Hench_ses-20170616T120000.nwb
Traceback (most recent call last):
  File "tools/populate_dandiset_asset_yamls.py", line 73, in main
    AssetMeta(**metadata)
  File "pydantic/main.py", line 362, in pydantic.main.BaseModel.__init__
pydantic.error_wrappers.ValidationError: 1 validation error for AssetMeta
identifier
  field required (type=value_error.missing)

sub-Hench/sub-Hench_ses-20170617T120000.nwb
Traceback (most recent call last):
  File "tools/populate_dandiset_asset_yamls.py", line 73, in main
    AssetMeta(**metadata)
  File "pydantic/main.py", line 362, in pydantic.main.BaseModel.__init__
pydantic.error_wrappers.ValidationError: 1 validation error for AssetMeta
identifier
  field required (type=value_error.missing)

sub-Hench/sub-Hench_ses-20170618T120000.nwb
Traceback (most recent call last):
  File "tools/populate_dandiset_asset_yamls.py", line 73, in main
    AssetMeta(**metadata)
  File "pydantic/main.py", line 362, in pydantic.main.BaseModel.__init__
pydantic.error_wrappers.ValidationError: 1 validation error for AssetMeta
identifier
  field required (type=value_error.missing)

sub-Lederberg/sub-Lederberg_ses-20171205T120000.nwb
Traceback (most recent call last):
  File "tools/populate_dandiset_asset_yamls.py", line 73, in main
    AssetMeta(**metadata)
  File "pydantic/main.py", line 362, in pydantic.main.BaseModel.__init__
pydantic.error_wrappers.ValidationError: 1 validation error for AssetMeta
identifier
  field required (type=value_error.missing)

sub-Lederberg/sub-Lederberg_ses-20171206T120000.nwb
Traceback (most recent call last):
  File "tools/populate_dandiset_asset_yamls.py", line 73, in main
    AssetMeta(**metadata)
  File "pydantic/main.py", line 362, in pydantic.main.BaseModel.__init__
pydantic.error_wrappers.ValidationError: 1 validation error for AssetMeta
identifier
  field required (type=value_error.missing)

sub-Lederberg/sub-Lederberg_ses-20171207T120000.nwb
Traceback (most recent call last):
  File "tools/populate_dandiset_asset_yamls.py", line 73, in main
    AssetMeta(**metadata)
  File "pydantic/main.py", line 362, in pydantic.main.BaseModel.__init__
pydantic.error_wrappers.ValidationError: 1 validation error for AssetMeta
identifier
  field required (type=value_error.missing)

sub-Lederberg/sub-Lederberg_ses-20171208T120000.nwb
Traceback (most recent call last):
  File "tools/populate_dandiset_asset_yamls.py", line 73, in main
    AssetMeta(**metadata)
  File "pydantic/main.py", line 362, in pydantic.main.BaseModel.__init__
pydantic.error_wrappers.ValidationError: 1 validation error for AssetMeta
identifier
  field required (type=value_error.missing)

sub-Lederberg/sub-Lederberg_ses-20171209T120000.nwb
Traceback (most recent call last):
  File "tools/populate_dandiset_asset_yamls.py", line 73, in main
    AssetMeta(**metadata)
  File "pydantic/main.py", line 362, in pydantic.main.BaseModel.__init__
pydantic.error_wrappers.ValidationError: 1 validation error for AssetMeta
identifier
  field required (type=value_error.missing)

sub-Lederberg/sub-Lederberg_ses-20171210T120000.nwb
Traceback (most recent call last):
  File "tools/populate_dandiset_asset_yamls.py", line 73, in main
    AssetMeta(**metadata)
  File "pydantic/main.py", line 362, in pydantic.main.BaseModel.__init__
pydantic.error_wrappers.ValidationError: 1 validation error for AssetMeta
identifier
  field required (type=value_error.missing)

sub-Lederberg/sub-Lederberg_ses-20171211T120000.nwb
Traceback (most recent call last):
  File "tools/populate_dandiset_asset_yamls.py", line 73, in main
    AssetMeta(**metadata)
  File "pydantic/main.py", line 362, in pydantic.main.BaseModel.__init__
pydantic.error_wrappers.ValidationError: 1 validation error for AssetMeta
identifier
  field required (type=value_error.missing)

sub-Moniz/sub-Moniz_ses-20170515T120000.nwb
Traceback (most recent call last):
  File "tools/populate_dandiset_asset_yamls.py", line 73, in main
    AssetMeta(**metadata)
  File "pydantic/main.py", line 362, in pydantic.main.BaseModel.__init__
pydantic.error_wrappers.ValidationError: 1 validation error for AssetMeta
identifier
  field required (type=value_error.missing)

sub-Moniz/sub-Moniz_ses-20170516T120000.nwb
Traceback (most recent call last):
  File "tools/populate_dandiset_asset_yamls.py", line 73, in main
    AssetMeta(**metadata)
  File "pydantic/main.py", line 362, in pydantic.main.BaseModel.__init__
pydantic.error_wrappers.ValidationError: 1 validation error for AssetMeta
identifier
  field required (type=value_error.missing)

sub-Moniz/sub-Moniz_ses-20170518T120000.nwb
Traceback (most recent call last):
  File "tools/populate_dandiset_asset_yamls.py", line 73, in main
    AssetMeta(**metadata)
  File "pydantic/main.py", line 362, in pydantic.main.BaseModel.__init__
pydantic.error_wrappers.ValidationError: 1 validation error for AssetMeta
identifier
  field required (type=value_error.missing)

sub-Muller/sub-Muller_ses-20170107T120000.nwb
Traceback (most recent call last):
  File "tools/populate_dandiset_asset_yamls.py", line 73, in main
    AssetMeta(**metadata)
  File "pydantic/main.py", line 362, in pydantic.main.BaseModel.__init__
pydantic.error_wrappers.ValidationError: 1 validation error for AssetMeta
identifier
  field required (type=value_error.missing)

sub-Muller/sub-Muller_ses-20170108T120000.nwb
Traceback (most recent call last):
  File "tools/populate_dandiset_asset_yamls.py", line 73, in main
    AssetMeta(**metadata)
  File "pydantic/main.py", line 362, in pydantic.main.BaseModel.__init__
pydantic.error_wrappers.ValidationError: 1 validation error for AssetMeta
identifier
  field required (type=value_error.missing)

sub-Muller/sub-Muller_ses-20170109T120000.nwb
Traceback (most recent call last):
  File "tools/populate_dandiset_asset_yamls.py", line 73, in main
    AssetMeta(**metadata)
  File "pydantic/main.py", line 362, in pydantic.main.BaseModel.__init__
pydantic.error_wrappers.ValidationError: 1 validation error for AssetMeta
identifier
  field required (type=value_error.missing)

sub-Radnitz/sub-Radnitz_ses-20170108T120000.nwb
Traceback (most recent call last):
  File "tools/populate_dandiset_asset_yamls.py", line 73, in main
    AssetMeta(**metadata)
  File "pydantic/main.py", line 362, in pydantic.main.BaseModel.__init__
pydantic.error_wrappers.ValidationError: 1 validation error for AssetMeta
identifier
  field required (type=value_error.missing)

sub-Radnitz/sub-Radnitz_ses-20170109T120000.nwb
Traceback (most recent call last):
  File "tools/populate_dandiset_asset_yamls.py", line 73, in main
    AssetMeta(**metadata)
  File "pydantic/main.py", line 362, in pydantic.main.BaseModel.__init__
pydantic.error_wrappers.ValidationError: 1 validation error for AssetMeta
identifier
  field required (type=value_error.missing)

sub-Radnitz/sub-Radnitz_ses-20170110T120000.nwb
Traceback (most recent call last):
  File "tools/populate_dandiset_asset_yamls.py", line 73, in main
    AssetMeta(**metadata)
  File "pydantic/main.py", line 362, in pydantic.main.BaseModel.__init__
pydantic.error_wrappers.ValidationError: 1 validation error for AssetMeta
identifier
  field required (type=value_error.missing)

sub-Radnitz/sub-Radnitz_ses-20170111T120000.nwb
Traceback (most recent call last):
  File "tools/populate_dandiset_asset_yamls.py", line 73, in main
    AssetMeta(**metadata)
  File "pydantic/main.py", line 362, in pydantic.main.BaseModel.__init__
pydantic.error_wrappers.ValidationError: 1 validation error for AssetMeta
identifier
  field required (type=value_error.missing)

sub-Radnitz/sub-Radnitz_ses-20170112T120000.nwb
Traceback (most recent call last):
  File "tools/populate_dandiset_asset_yamls.py", line 73, in main
    AssetMeta(**metadata)
  File "pydantic/main.py", line 362, in pydantic.main.BaseModel.__init__
pydantic.error_wrappers.ValidationError: 1 validation error for AssetMeta
identifier
  field required (type=value_error.missing)

sub-Richards/sub-Richards_ses-20171029T120000.nwb
Traceback (most recent call last):
  File "tools/populate_dandiset_asset_yamls.py", line 73, in main
    AssetMeta(**metadata)
  File "pydantic/main.py", line 362, in pydantic.main.BaseModel.__init__
pydantic.error_wrappers.ValidationError: 1 validation error for AssetMeta
identifier
  field required (type=value_error.missing)

sub-Richards/sub-Richards_ses-20171030T120000.nwb
Traceback (most recent call last):
  File "tools/populate_dandiset_asset_yamls.py", line 73, in main
    AssetMeta(**metadata)
  File "pydantic/main.py", line 362, in pydantic.main.BaseModel.__init__
pydantic.error_wrappers.ValidationError: 1 validation error for AssetMeta
identifier
  field required (type=value_error.missing)

sub-Richards/sub-Richards_ses-20171031T120000.nwb
Traceback (most recent call last):
  File "tools/populate_dandiset_asset_yamls.py", line 73, in main
    AssetMeta(**metadata)
  File "pydantic/main.py", line 362, in pydantic.main.BaseModel.__init__
pydantic.error_wrappers.ValidationError: 1 validation error for AssetMeta
identifier
  field required (type=value_error.missing)

sub-Richards/sub-Richards_ses-20171101T120000.nwb
Traceback (most recent call last):
  File "tools/populate_dandiset_asset_yamls.py", line 73, in main
    AssetMeta(**metadata)
  File "pydantic/main.py", line 362, in pydantic.main.BaseModel.__init__
pydantic.error_wrappers.ValidationError: 1 validation error for AssetMeta
identifier
  field required (type=value_error.missing)

sub-Richards/sub-Richards_ses-20171102T120000.nwb
Traceback (most recent call last):
  File "tools/populate_dandiset_asset_yamls.py", line 73, in main
    AssetMeta(**metadata)
  File "pydantic/main.py", line 362, in pydantic.main.BaseModel.__init__
pydantic.error_wrappers.ValidationError: 1 validation error for AssetMeta
identifier
  field required (type=value_error.missing)

sub-Tatum/sub-Tatum_ses-20171206T120000.nwb
Traceback (most recent call last):
  File "tools/populate_dandiset_asset_yamls.py", line 73, in main
    AssetMeta(**metadata)
  File "pydantic/main.py", line 362, in pydantic.main.BaseModel.__init__
pydantic.error_wrappers.ValidationError: 1 validation error for AssetMeta
identifier
  field required (type=value_error.missing)

sub-Tatum/sub-Tatum_ses-20171207T120000.nwb
Traceback (most recent call last):
  File "tools/populate_dandiset_asset_yamls.py", line 73, in main
    AssetMeta(**metadata)
  File "pydantic/main.py", line 362, in pydantic.main.BaseModel.__init__
pydantic.error_wrappers.ValidationError: 1 validation error for AssetMeta
identifier
  field required (type=value_error.missing)

sub-Tatum/sub-Tatum_ses-20171208T120000.nwb
Traceback (most recent call last):
  File "tools/populate_dandiset_asset_yamls.py", line 73, in main
    AssetMeta(**metadata)
  File "pydantic/main.py", line 362, in pydantic.main.BaseModel.__init__
pydantic.error_wrappers.ValidationError: 1 validation error for AssetMeta
identifier
  field required (type=value_error.missing)

sub-Tatum/sub-Tatum_ses-20171209T120000.nwb
Traceback (most recent call last):
  File "tools/populate_dandiset_asset_yamls.py", line 73, in main
    AssetMeta(**metadata)
  File "pydantic/main.py", line 362, in pydantic.main.BaseModel.__init__
pydantic.error_wrappers.ValidationError: 1 validation error for AssetMeta
identifier
  field required (type=value_error.missing)

sub-Theiler/sub-Theiler_ses-20171011T120000.nwb
Traceback (most recent call last):
  File "tools/populate_dandiset_asset_yamls.py", line 73, in main
    AssetMeta(**metadata)
  File "pydantic/main.py", line 362, in pydantic.main.BaseModel.__init__
pydantic.error_wrappers.ValidationError: 1 validation error for AssetMeta
identifier
  field required (type=value_error.missing)

